Workbook

Sheet README
A1: Zumi Holdings — 24-Month Cashflow & Runway Analysis
A3: ## Your assignment
A4: The board meets in 9 days. They want one number: how many months of cash does Zumi have. The CEO's gut says 18. The CFO's gut says 11. You will end the argument with a model.
A6: ## What you have
A7: Tab 'Historical_Monthly' — 24 months of P&L and balance sheet snapshot data, by brand.
A8: Tab 'AR_Aging' — receivables by customer, aging buckets (0-30, 31-60, 61-90, 90+).
A9: Tab 'AP_Schedule' — payables and their due dates.
A10: Tab 'Loans' — three facilities (overdraft, term loan, equipment lease) with principal, rate, and amortization terms.
A11: Tab 'CapEx_Plan' — committed capex over the next 12 months.
A12: Tab 'Tax_Calendar' — VAT, PAYE, CIT due dates and amounts.
A13: Tab 'Assumptions' — drivers for forward projection. You can change them. Do not change historicals.
A15: ## What you must build
... A22: When you write the verdict, write it like the CFO is going to forward it to the chairman. Direct. Specific. No hedging.

Sheet Historical_Monthly
A1: Month | B1: Brand | C1: Revenue_NGN | D1: COGS_NGN | E1: Gross_Profit_NGN | F1: Opex_NGN | G1: EBITDA_NGN | H1: Cash_Collected_NGN | I1: Cash_Paid_NGN | J1: Closing_Cash_NGN | K1: Headcount
A2: 2023-10 | B2: Zumi Eats | C2: 19905249 | D2: 12862026 | E2: 7043223 | F2: 6869812 | G2: 173411 | H2: 18909987 | I2: 19502123 | K2: 38
A3: 2023-10 | B3: Zumi Mart | C3: 34991114 | D3: 27559196 | E3: 7431918 | F3: 7235380 | G3: 196538 | H3: 33241558 | I3: 34181676 | K3: 52
A4: 2023-10 | B4: Zumi Logistics | C4: 13047516 | D4: 7516394 | E4: 5531122 | F4: 4102356 | G4: 1428766 | H4: 10177062 | I4: 11735091 | J4: 88909717 | K4: 28
A5: 2023-11 | B5: Zumi Eats | C5: 21253937 | D5: 13498682 | E5: 7755255 | F5: 6905491 | G5: 849764 | H5: 20191240 | I5: 20212304 | K5: 38
A6: 2023-11 | B6: Zumi Mart | C6: 36672771 | D6: 28809820 | E6: 7862951 | F6: 7552162 | G6: 310789 | H6: 34839132 | I6: 35656077 | K6: 52
A7: 2023-11 | B7: Zumi Logistics | C7: 13479393 | D7: 8066111 | E7: 5413282 | F7: 4170885 | G7: 1242397 | H7: 10513927 | I7: 12467490 | J7: 86118145 | K7: 28
A8: 2023-12 | B8: Zumi Eats | C8: 22268307 | D8: 13922612 | E8: 8345695 | F8: 6818127 | G8: 1527568 | H8: 21154892 | I8: 20893693 | K8: 38
A9: 2023-12 | B9: Zumi Mart | C9: 38888162 | D9: 30172290 | E9: 8715872 | F9: 7454550 | G9: 1261322 | H9: 36943754 | I9: 36902337 | K9: 52
A10: 2023-12 | B10: Zumi Logistics | C10: 13910505 | D10: 8131330 | E10: 5779175 | F10: 4328010 | G10: 1451165 | H10: 10850194 | I10: 12212562 | J10: 85058393 | K10: 28
A11: 2024-01 | B11: Zumi Eats | C11: 24351872 | D11: 15524873 | E11: 8826999 | F11: 7135445 | G11: 1691554 | H11: 23134278 | I11: 22788162 | K11: 38
A12: 2024-01 | B12: Zumi Mart | C12: 39999722 | D12: 31608864 | E12: 8390858 | F12: 7636250 | G12: 754608 | H12: 37999736 | I12: 39264817 | K12: 52
A13: 2024-01 | B13: Zumi Logistics | C13: 14679799 | D13: 8762748 | E13: 5917051 | F13: 4419132 | G13: 1497919 | H13: 11450243 | I13: 13415980 | J13: 82173691 | K13: 28
A14: 2024-02 | B14: Zumi Eats | C14: 25779628 | D14: 16330515 | E14: 9449113 | F14: 7005958 | G14: 2443155 | H14: 24490647 | I14: 22878194 | K14: 38
A15: 2024-02 | B15: Zumi Mart | C15: 43333409 | D15: 34269940 | E15: 9063469 | F15: 7665991 | G15: 1397478 | H15: 41166739 | I15: 41205017 | K15: 52
A16: 2024-02 | B16: Zumi Logistics | C16: 16528392 | D16: 9490585 | E16: 7037807 | F16: 4297986 | G16: 2739821 | H16: 12892146 | I16: 13837368 | J16: 82802644 | K16: 28
A17: 2024-03 | B17: Zumi Eats | C17: 26159931 | D17: 17210780 | E17: 8949151 | F17: 7373366 | G17: 1575785 | H17: 24851934 | I17: 24506162 | K17: 38
A18: 2024-03 | B18: Zumi Mart | C18: 45276538 | D18: 35676900 | E18: 9599638 | F18: 7876543 | G18: 1723095 | H18: 43012711 | I18: 43571520 | K18: 52
A19: 2024-03 | B19: Zumi Logistics | C19: 16940210 | D19: 9739531 | E19: 7200679 | F19: 4515725 | G19: 2684954 | H19: 13213364 | I19: 14193813 | J19: 81609158 | K19: 28
A20: 2024-04 | B20: Zumi Eats | C20: 27644246 | D20: 17912969 | E20: 9731277 | F20: 7204038 | G20: 2527239 | H20: 26262034 | I20: 24852098 | K20: 39
A21: 2024-04 | B21: Zumi Mart | C21: 49003295 | D21: 37271364 | E21: 11731931 | F21: 7958536 | G21: 3773395 | H21: 46553130 | I21: 45605931 | K21: 53
A22: 2024-04 | B22: Zumi Logistics | C22: 18013682 | D22: 10819389 | E22: 7194293 | F22: 4502013 | G22: 2692280 | H22: 14050672 | I22: 15173465 | J22: 64843500 | K22: 29
A23: 2024-05 | B23: Zumi Eats | C23: 28737993 | D23: 18067960 | E23: 10670033 | F23: 7425014 | G23: 3245019 | H23: 27301093 | I23: 25430182 | K23: 39
A24: 2024-05 | B24: Zumi Mart | C24: 47121352 | D24: 36041304 | E24: 11080048 | F24: 8244672 | G24: 2835376 | H24: 44765284 | I24: 44306307 | K24: 53
A25: 2024-05 | B25: Zumi Logistics | C25: 17344105 | D25: 10189129 | E25: 7154976 | F25: 4456875 | G25: 2698101 | H25: 13528402 | I25: 14936632 | J25: 65765158 | K25: 29
A26: 2024-06 | B26: Zumi Eats | C26: 28130889 | D26: 18439697 | E26: 9691192 | F26: 7478240 | G26: 2212952 | H26: 26724345 | I26: 25549623 | K26: 39
A27: 2024-06 | B27: Zumi Mart | C27: 48600026 | D27: 37656436 | E27: 10943590 | F27: 7972710 | G27: 2970880 | H27: 46170025 | I27: 46436168 | K27: 53
A28: 2024-06 | B28: Zumi Logistics | C28: 17469505 | D28: 10461241 | E28: 7008264 | F28: 4651466 | G28: 2356798 | H28: 13626214 | I28: 14903831 | J28: 65396120 | K28: 29
A29: 2024-07 | B29: Zumi Eats | C29: 26900564 | D29: 17026925 | E29: 9873639 | F29: 7719908 | G29: 2153731 | H29: 25555536 | I29: 24507280 | K29: 39
A30: 2024-07 | B30: Zumi Mart | C30: 47208495 | D30: 36113760 | E30: 11094735 | F30: 8386507 | G30: 2708228 | H30: 44848070 | I30: 43787349 | K30: 53
A31: 2024-07 | B31: Zumi Logistics | C31: 16968644 | D31: 9759124 | E31: 7209520 | F31: 4640733 | G31: 2568787 | H31: 13235542 | I31: 14406446 | J31: 66334193 | K31: 29
A32: 2024-08 | B32: Zumi Eats | C32: 27220297 | D32: 17827646 | E32: 9392651 | F32: 7594355 | G32: 1798296 | H32: 25859282 | I32: 25112426 | K32: 39
A33: 2024-08 | B33: Zumi Mart | C33: 45379256 | D33: 36024404 | E33: 9354852 | F33: 8443126 | G33: 911726 | H33: 43110293 | I33: 45302584 | K33: 53
A34: 2024-08 | B34: Zumi Logistics | C34: 17163695 | D34: 9789735 | E34: 7373960 | F34: 4806793 | G34: 2567167 | H34: 13387682 | I34: 14324560 | J34: 63951880 | K34: 29
A35: 2024-09 | B35: Zumi Eats | C35: 27396506 | D35: 17106097 | E35: 10290409 | F35: 7611480 | G35: 2678929 | H35: 26026681 | I35: 24812712 | K35: 39
A36: 2024-09 | B36: Zumi Mart | C36: 45399334 | D36: 35243004 | E36: 10156330 | F36: 8494283 | G36: 1662047 | H36: 43129367 | I36: 44217954 | K36: 53
A37: 2024-09 | B37: Zumi Logistics | C37: 16945225 | D37: 10123363 | E37: 6821862 | F37: 4697586 | G37: 2124276 | H37: 13217276 | I37: 14571877 | J37: 62722661 | K37: 29
A38: 2024-10 | B38: Zumi Eats | C38: 26756739 | D38: 17619719 | E38: 9137020 | F38: 7860690 | G38: 1276330 | H38: 25418902 | I38: 25090917 | K38: 40
A39: 2024-10 | B39: Zumi Mart | C39: 47400919 | D39: 37015756 | E39: 10385163 | F39: 8441943 | G39: 1943220 | H39: 45030873 | I39: 45317404 | K39: 54
A40: 2024-10 | B40: Zumi Logistics | C40: 17254809 | D40: 10012266 | E40: 7242543 | F40: 4928476 | G40: 2314067 | H40: 13458751 | I40: 14981529 | J40: 121241337 | K40: 30
...

Sheet AR_Aging
A1: Customer | B1: Brand | C1: Invoice_ID | D1: Invoice_Date | E1: Due_Date | F1: Amount_NGN | G1: Days_Past_Due | H1: Bucket
A2: Dangote Group | B2: Zumi Logistics | C2: INV-50001 | D2: 2025-07-24 | E2: 2025-08-23 | F2: 4200000 | G2: 38 | H2: 31-60
A3: Dangote Group | B3: Zumi Logistics | C3: INV-50002 | D3: 2025-07-13 | E3: 2025-08-12 | F3: 4200000 | G3: 49 | H3: 31-60
A4: MTN Nigeria | B4: Zumi Logistics | C4: INV-50003 | D4: 2025-06-12 | E4: 2025-07-12 | F4: 3100000 | G4: 80 | H4: 61-90
A5: MTN Nigeria | B5: Zumi Logistics | C5: INV-50004 | D5: 2025-07-23 | E5: 2025-08-22 | F5: 3100000 | G5: 39 | H5: 31-60
A6: Flutterwave | B6: Zumi Logistics | C6: INV-50005 | D6: 2025-07-24 | E6: 2025-08-23 | F6: 3800000 | G6: 38 | H6: 31-60
A7: GTBank | B7: Zumi Logistics | C7: INV-50006 | D7: 2025-08-03 | E7: 2025-09-02 | F7: 1200000 | G7: 28 | H7: 1-30
A8: GTBank | B8: Zumi Logistics | C8: INV-50007 | D8: 2025-07-30 | E8: 2025-08-29 | F8: 1200000 | G8: 32 | H8: 31-60
A9: Access Bank | B9: Zumi Logistics | C9: INV-50008 | D9: 2025-08-07 | E9: 2025-09-06 | F9: 633333 | G9: 24 | H9: 1-30
A10: Access Bank | B10: Zumi Logistics | C10: INV-50009 | D10: 2025-07-05 | E10: 2025-08-04 | F10: 633333 | G10: 57 | H10: 31-60
A11: Access Bank | B11: Zumi Logistics | C11: INV-50010 | D11: 2025-07-04 | E11: 2025-08-03 | F11: 633333 | G11: 58 | H11: 31-60
A12: Sterling Bank | B12: Zumi Logistics | C12: INV-50011 | D12: 2025-09-07 | E12: 2025-10-07 | F12: 1400000 | G12: 0 | H12: Current
A13: Office Lunch B2B Misc | B13: Zumi Eats | C13: INV-50012 | D13: 2025-08-10 | E13: 2025-09-09 | F13: 2100000 | G13: 21 | H13: 1-30
... A25: Hotel Supply Contract | B25: Zumi Mart | C25: INV-50024 | D25: 2025-09-11 | E25: 2025-10-11 | F25: 1533333 | G25: 0 | H25: Current

Sheet AP_Schedule
A1: Vendor | B1: Bill_ID | C1: Bill_Date | D1: Due_Date | E1: Amount_NGN | F1: Status
A2: FreshFarms NG | B2: BILL-9001 | C2: 2025-09-15 | D2: 2025-10-15 | E2: 4200000 | F2: Open
A3: Distell Wholesale | B3: BILL-9002 | C3: 2025-09-20 | D3: 2025-10-20 | E3: 6800000 | F3: Open
A4: PZ Cussons | B4: BILL-9003 | C4: 2025-09-22 | D4: 2025-10-22 | E4: 3900000 | F4: Open
A5: NNPC Retail | B5: BILL-9004 | C5: 2025-09-25 | D5: 2025-10-10 | E5: 2400000 | F5: Open
A6: Property Holdings Ltd | B6: BILL-9005 | C6: 2025-10-01 | D6: 2025-10-05 | E6: 2500000 | F6: Open
A7: Bento Africa Payroll | B7: BILL-9006 | C7: 2025-10-25 | D7: 2025-10-25 | E7: 12400000 | F7: Recurring
A8: Andersen Tax | B8: BILL-9007 | C8: 2025-09-30 | D8: 2025-10-30 | E8: 1200000 | F8: Open
A9: Meta Platforms | B9: BILL-9008 | C9: 2025-09-28 | D9: 2025-10-12 | E9: 1640000 | F9: Open
A10: PackPro Ltd | B10: BILL-9009 | C10: 2025-09-26 | D10: 2025-10-26 | E10: 980000 | F10: Open
A11: Vehicle Maintenance Co | B11: BILL-9010 | C11: 2025-09-29 | D11: 2025-10-29 | E11: 760000 | F11: Open

Sheet Loans
A1: Facility | B1: Lender | C1: Principal_NGN | D1: Interest_Rate | E1: Term_Months | F1: Months_Remaining | G1: Monthly_Payment_NGN | H1: Notes
A2: Overdraft | B2: GTBank | C2: 25000000 | D2: 0.265 | E2: 12 | F2: 8 | G2: 2350000 | H2: Revolving
A3: Term Loan | B3: Bank of Industry | C3: 80000000 | D3: 0.18 | E3: 60 | F3: 41 | G3: 2010000 | H3: Equipment financing
A4: Equipment Lease | B4: Renaissance Capital | C4: 32000000 | D4: 0.22 | E4: 36 | F4: 19 | G4: 1220000 | H4: Refrigeration units

Sheet CapEx_Plan
A1: Month | B1: Item | C1: Brand | D1: Amount_NGN | E1: Status
A2: 2025-10 | B2: Cold storage truck | C2: Zumi Logistics | D2: 14000000 | E2: Committed
A3: 2025-11 | B3: POS upgrade Lekki + VI | C3: Zumi Mart | D3: 6800000 | E3: Committed
A4: 2026-01 | B4: Cloud kitchen Abuja fit-out | C4: Zumi Eats | D4: 22000000 | E4: Planned
A5: 2026-03 | B5: Warehouse racking phase 2 | C5: Zumi Mart | D5: 9400000 | E5: Planned
A6: 2026-06 | B6: Fleet expansion (4 vehicles) | C6: Zumi Logistics | D6: 28000000 | E6: Planned

Sheet Tax_Calendar
A1: Tax_Type | B1: Period | C1: Due_Date | D1: Estimated_Amount_NGN | E1: Notes
A2: VAT | B2: 2025-09 | C2: 2025-10-21 | D2: 4200000 | E2: FIRS
A3: PAYE | B3: 2025-09 | C3: 2025-10-10 | D3: 1840000 | E3: LIRS
A4: CIT 1st Instalment | B4: FY2025 | C4: 2025-12-31 | D4: 18400000 | E4: Self-assessed
A5: VAT | B5: 2025-10 | C5: 2025-11-21 | D5: 4400000 | E5: Estimated
A6: PAYE | B6: 2025-10 | C6: 2025-11-10 | D6: 1900000 | E6: Estimated
A7: WHT Remittance | B7: 2025-09 | C7: 2025-10-21 | D7: 720000

Sheet Assumptions
A1: Driver | B1: Base | C1: Upside | D1: Downside | E1: Notes
A2: Revenue growth m/m | B2: 0.025 | C2: 0.045 | D2: 0.005 | E2: Group blended
A3: COGS as % of revenue | B3: 0.66 | C3: 0.62 | D3: 0.7 | E3: Inverse of GM
A4: Opex growth m/m | B4: 0.012 | C4: 0.008 | D4: 0.02
A5: AR collection days | B5: 38 | C5: 28 | D5: 55 | E5: Logistics drags this
A6: AP payment days | B6: 32 | C6: 45 | D6: 22
A7: FX shock NGN/USD | B7: 0 | C7: -0.05 | D7: 0.15 | E7: + means devaluation
A8: Top-3 customer payment delay (days) | B8: 0 | C8: 0 | D8: 60
A9: Equity raise expected (NGN) | B9: 0 | C9: 120000000 | D9: 0 | E9: Q1 2026 if at all

Sheet Cash_Forecast_12M
A1: Month | B1: Opening Cash | C1: Revenue | D1: Collections | E1: COGS | F1: OpEx | G1: Loan Payments | H1: CapEx | I1: Tax Payments | J1: Total Outflows | K1: Net Cash Flow | L1: Closing Cash
A2: 2025-10 | B2: =SUMIF(Historical_Monthly!A:A,"2025-09",Historical_Monthly!J:J) -> 122990111 | C2: =SUMIF(Historical_Monthly!A:A,"2025-09",Historical_Monthly!C:C)*(1+Assumptions!B2) -> 1.2615601e+08 | D2: =C2*0.95 -> 1.1984821e+08 | E2: =C2*Assumptions!$B$3 -> 83262969 | F2: =SUMIF(Historical_Monthly!A:A,"2025-09",Historical_Monthly!F:F)*(1+Assumptions!$B$4) -> 24730828 | G2: =SUM(Loans!$G$2:$G$4) -> 5580000 | H2: =SUMIF(CapEx_Plan!A:A,A2,CapEx_Plan!D:D) -> 14000000 | I2: 6760000 | J2: =E2+F2+G2+H2+I2 -> 1.343338e+08 | K2: =D2-J2 -> -14485584 | L2: =B2+K2 -> 1.0850453e+08
A3: 2025-11 | B3: =L2 -> 1.0850453e+08 | C3: =C2*(1+Assumptions!$B$2) -> 1.2930991e+08 | D3: =C3*0.95 -> 1.2284442e+08 | E3: =C3*Assumptions!$B$3 -> 85344543 | F3: =F2*(1+Assumptions!$B$4) -> 25027598 | G3: =SUM(Loans!$G$2:$G$4) -> 5580000 | H3: =SUMIF(CapEx_Plan!A:A,A3,CapEx_Plan!D:D) -> 6800000 | I3: 6300000 | J3: =E3+F3+G3+H3+I3 -> 1.2905214e+08 | K3: =D3-J3 -> -6207722.7 | L3: =B3+K3 -> 1.022968e+08
A4: 2025-12 | B4: =L3 -> 1.022968e+08 | C4: =C3*(1+Assumptions!$B$2) -> 1.3254266e+08 | D4: =C4*0.95 -> 1.2591553e+08 | E4: =C4*Assumptions!$B$3 -> 87478157 | F4: =F3*(1+Assumptions!$B$4) -> 25327929 | G4: =SUM(Loans!$G$2:$G$4) -> 5580000 | H4: =SUMIF(CapEx_Plan!A:A,A4,CapEx_Plan!D:D) -> 0 | I4: 18400000 | J4: =E4+F4+G4+H4+I4 -> 1.3678609e+08 | K4: =D4-J4 -> -10870557 | L4: =B4+K4 -> 91426247
A5: 2026-01 | B5: =L4 -> 91426247 | C5: =C4*(1+Assumptions!$B$2) -> 1.3585623e+08 | D5: =C5*0.95 -> 1.2906342e+08 | E5: =C5*Assumptions!$B$3 -> 89665111 | F5: =F4*(1+Assumptions!$B$4) -> 25631864 | G5: =SUM(Loans!$G$2:$G$4) -> 5580000 | H5: =SUMIF(CapEx_Plan!A:A,A5,CapEx_Plan!D:D) -> 22000000 | I5: 0 | J5: =E5+F5+G5+H5+I5 -> 1.4287698e+08 | K5: =D5-J5 -> -13813558 | L5: =B5+K5 -> 77612690
A6: 2026-02 | B6: =L5 -> 77612690 | C6: =C5*(1+Assumptions!$B$2) -> 1.3925263e+08 | D6: =C6*0.95 -> 1.3229e+08 | E6: =C6*Assumptions!$B$3 -> 91906739 | F6: =F5*(1+Assumptions!$B$4) -> 25939447 | G6: =SUM(Loans!$G$2:$G$4) -> 5580000 | H6: =SUMIF(CapEx_Plan!A:A,A6,CapEx_Plan!D:D) -> 0 | I6: 0 | J6: =E6+F6+G6+H6+I6 -> 1.2342619e+08 | K6: =D6-J6 -> 8863817.4 | L6: =B6+K6 -> 86476507
A7: 2026-03 | B7: =L6 -> 86476507 | C7: =C6*(1+Assumptions!$B$2) -> 1.4273395e+08 | D7: =C7*0.95 -> 1.3559725e+08 | E7: =C7*Assumptions!$B$3 -> 94204407 | F7: =F6*(1+Assumptions!$B$4) -> 26250720 | G7: =SUM(Loans!$G$2:$G$4) -> 5580000 | H7: =SUMIF(CapEx_Plan!A:A,A7,CapEx_Plan!D:D) -> 9400000 | I7: 0 | J7: =E7+F7+G7+H7+I7 -> 1.3543513e+08 | K7: =D7-J7 -> 162125.67 | L7: =B7+K7 -> 86638633
A8: 2026-04 | B8: =L7 -> 86638633 | C8: =C7*(1+Assumptions!$B$2) -> 1.463023e+08 | D8: =C8*0.95 -> 1.3898718e+08 | E8: =C8*Assumptions!$B$3 -> 96559517 | F8: =F7*(1+Assumptions!$B$4) -> 26565729 | G8: =SUM(Loans!$G$2:$G$4) -> 5580000 | H8: =SUMIF(CapEx_Plan!A:A,A8,CapEx_Plan!D:D) -> 0 | I8: 0 | J8: =E8+F8+G8+H8+I8 -> 1.2870525e+08 | K8: =D8-J8 -> 10281938 | L8: =B8+K8 -> 96920571
A9: 2026-05 | B9: =L8 -> 96920571 | C9: =C8*(1+Assumptions!$B$2) -> 1.4995986e+08 | D9: =C9*0.95 -> 1.4246186e+08 | E9: =C9*Assumptions!$B$3 -> 98973505 | F9: =F8*(1+Assumptions!$B$4) -> 26884517 | G9: =SUM(Loans!$G$2:$G$4) -> 5580000 | H9: =SUMIF(CapEx_Plan!A:A,A9,CapEx_Plan!D:D) -> 0 | I9: 0 | J9: =E9+F9+G9+H9+I9 -> 1.3143802e+08 | K9: =D9-J9 -> 11023841 | L9: =B9+K9 -> 1.0794441e+08
A10: 2026-06 | B10: =L9 -> 1.0794441e+08 | C10: =C9*(1+Assumptions!$B$2) -> 1.5370885e+08 | D10: =C10*0.95 -> 1.4602341e+08 | E10: =C10*Assumptions!$B$3 -> 1.0144784e+08 | F10: =F9*(1+Assumptions!$B$4) -> 27207131 | G10: =SUM(Loans!$G$2:$G$4) -> 5580000 | H10: =SUMIF(CapEx_Plan!A:A,A10,CapEx_Plan!D:D) -> 28000000 | I10: 0 | J10: =E10+F10+G10+H10+I10 -> 1.6223497e+08 | K10: =D10-J10 -> -16211564 | L10: =B10+K10 -> 91732848
A11: 2026-07 | B11: =L10 -> 91732848 | C11: =C10*(1+Assumptions!$B$2) -> 1.5755157e+08 | D11: =C11*0.95 -> 1.49674e+08 | E11: =C11*Assumptions!$B$3 -> 1.0398404e+08 | F11: =F10*(1+Assumptions!$B$4) -> 27533617 | G11: =SUM(Loans!$G$2:$G$4) -> 5580000 | H11: =SUMIF(CapEx_Plan!A:A,A11,CapEx_Plan!D:D) -> 0 | I11: 0 | J11: =E11+F11+G11+H11+I11 -> 1.3709766e+08 | K11: =D11-J11 -> 12576339 | L11: =B11+K11 -> 1.0430919e+08
A12: 2026-08 | B12: =L11 -> 1.0430919e+08 | C12: =C11*(1+Assumptions!$B$2) -> 1.6149036e+08 | D12: =C12*0.95 -> 1.5341585e+08 | E12: =C12*Assumptions!$B$3 -> 1.0658364e+08 | F12: =F11*(1+Assumptions!$B$4) -> 27864020 | G12: =SUM(Loans!$G$2:$G$4) -> 5580000 | H12: =SUMIF(CapEx_Plan!A:A,A12,CapEx_Plan!D:D) -> 0 | I12: 0 | J12: =E12+F12+G12+H12+I12 -> 1.4002766e+08 | K12: =D12-J12 -> 13388185 | L12: =B12+K12 -> 1.1769737e+08
A13: 2026-09 | B13: =L12 -> 1.1769737e+08 | C13: =C12*(1+Assumptions!$B$2) -> 1.6552762e+08 | D13: =C13*0.95 -> 1.5725124e+08 | E13: =C13*Assumptions!$B$3 -> 1.0924823e+08 | F13: =F12*(1+Assumptions!$B$4) -> 28198389 | G13: =SUM(Loans!$G$2:$G$4) -> 5580000 | H13: =SUMIF(CapEx_Plan!A:A,A13,CapEx_Plan!D:D) -> 0 | I13: 0 | J13: =E13+F13+G13+H13+I13 -> 1.4302662e+08 | K13: =D13-J13 -> 14224622 | L13: =B13+K13 -> 1.3192199e+08

Sheet Runway
A1: Month | B1: Total Cash Collected | C1: Total Cash Paid | D1: Net Cash Flow
A2: 2025-07 | B2: =SUMIF(Historical_Monthly!A:A,"2025-07",Historical_Monthly!H:H) -> 112017999 | C2: =SUMIF(Historical_Monthly!A:A,"2025-07",Historical_Monthly!I:I) -> 107921424 | D2: =B2-C2 -> 4096575
A3: 2025-08 | B3: =SUMIF(Historical_Monthly!A:A,"2025-08",Historical_Monthly!H:H) -> 110190652 | C3: =SUMIF(Historical_Monthly!A:A,"2025-08",Historical_Monthly!I:I) -> 106488362 | D3: =B3-C3 -> 3702290
A4: 2025-09 | B4: =SUMIF(Historical_Monthly!A:A,"2025-09",Historical_Monthly!H:H) -> 113041518 | C4: =SUMIF(Historical_Monthly!A:A,"2025-09",Historical_Monthly!I:I) -> 110687618 | D4: =B4-C4 -> 2353900
A6: Trailing 3M Avg Net Cash Flow | D6: =AVERAGE(D2:D4) -> 3384255
A10: Base Case — Months of Runway | D10: {=IFERROR(MATCH(TRUE,Cash_Forecast_12M!L2:L13<=0,0),"12+ months — cash stays positive")} -> 12+ months — cash stays positive
A12: Worst Case — Months of Runway | D12: {=MATCH(TRUE,Stress_Test!K3:K14<=0,0)} -> 6
A14: Best Case — Months of Runway | D14: {=IFERROR(MATCH(TRUE,Stress_Test!L19:L30<=0,0),"12+ months — cash stays positive")} -> 12+ months — cash stays positive
A18: AP VENDOR ANALYSIS
A19: Largest AP Vendor Name | B19: {=_xlfn.XLOOKUP(MAX(AP_Schedule!E:E),AP_Schedule!E:E,AP_Schedule!A:A)} -> Bento Africa Payroll
A20: Amount Due | B20: {=MAX(AP_Schedule!E:E)} -> 12400000
A21: Due Date | B21: {=_xlfn.XLOOKUP(MAX(AP_Schedule!E:E),AP_Schedule!E:E,AP_Schedule!D:D)} -> 2025-10-25
A22: Status | B22: =_xlfn.XLOOKUP(MAX(AP_Schedule!E:E),AP_Schedule!E:E,AP_Schedule!F:F) -> Recurring

Sheet Stress_Test
A1: WORST CASE SCENARIO
A2: Month | B2: Opening Cash | C2: Worst-Case Collections | D2: COGS | E2: OpEx | F2: Loan Payments | G2: CapEx | H2: Tax Payments | I2: Total Outflows | J2: Net Cash Flow | K2: Closing Cash
A3: 2025-10 | B3: =Cash_Forecast_12M!B2 -> 122990111 | C3: =(Cash_Forecast_12M!C2*0.8*0.9875*0.95)-18400000 -> 76280088 | D3: =Cash_Forecast_12M!E2*0.8 -> 66610375 | E3: =Cash_Forecast_12M!F2 -> 24730828 | F3: =SUM(Loans!$G$2:$G$4) -> 5580000 | G3: =Cash_Forecast_12M!H2 -> 14000000 | H3: =Cash_Forecast_12M!I2 -> 6760000 | I3: =D3+E3+F3+G3+H3 -> 1.176812e+08 | J3: =C3-I3 -> -41401115 | K3: =B3+J3 -> 81588996
A4: 2025-11 | B4: =K3 -> 81588996 | C4: =(Cash_Forecast_12M!C3*0.8*0.9875*0.95)-18400000 -> 78647091 | D4: =Cash_Forecast_12M!E3*0.8 -> 68275635 | E4: =Cash_Forecast_12M!F3 -> 25027598 | F4: =SUM(Loans!$G$2:$G$4) -> 5580000 | G4: =Cash_Forecast_12M!H3 -> 6800000 | H4: =Cash_Forecast_12M!I3 -> 6300000 | I4: =D4+E4+F4+G4+H4 -> 1.1198323e+08 | J4: =C4-I4 -> -33336142 | K4: =B4+J4 -> 48252854
A5: 2025-12 | B5: =K4 -> 48252854 | C5: =Cash_Forecast_12M!C4*0.8*0.9875*0.95 -> 99473268 | D5: =Cash_Forecast_12M!E4*0.8 -> 69982526 | E5: =Cash_Forecast_12M!F4 -> 25327929 | F5: =SUM(Loans!$G$2:$G$4) -> 5580000 | G5: =Cash_Forecast_12M!H4 -> 0 | H5: =Cash_Forecast_12M!I4 -> 18400000 | I5: =D5+E5+F5+G5+H5 -> 1.1929045e+08 | J5: =C5-I5 -> -19817187 | K5: =B5+J5 -> 28435668
A6: 2026-01 | B6: =K5 -> 28435668 | C6: =Cash_Forecast_12M!C5*0.8*0.9875*0.95 -> 1.019601e+08 | D6: =Cash_Forecast_12M!E5*0.8 -> 71732089 | E6: =Cash_Forecast_12M!F5 -> 25631864 | F6: =SUM(Loans!$G$2:$G$4) -> 5580000 | G6: =Cash_Forecast_12M!H5 -> 22000000 | H6: =Cash_Forecast_12M!I5 -> 0 | I6: =D6+E6+F6+G6+H6 -> 1.2494395e+08 | J6: =C6-I6 -> -22983853 | K6: =B6+J6 -> 5451814.3
A7: 2026-02 | B7: =K6 -> 5451814.3 | C7: =Cash_Forecast_12M!C6*0.8*0.9875*0.95 -> 1.045091e+08 | D7: =Cash_Forecast_12M!E6*0.8 -> 73525391 | E7: =Cash_Forecast_12M!F6 -> 25939447 | F7: =SUM(Loans!$G$2:$G$4) -> 5580000 | G7: =Cash_Forecast_12M!H6 -> 0 | H7: =Cash_Forecast_12M!I6 -> 0 | I7: =D7+E7+F7+G7+H7 -> 1.0504484e+08 | J7: =C7-I7 -> -535735.39 | K7: =B7+J7 -> 4916078.9
A8: 2026-03 | B8: =K7 -> 4916078.9 | C8: =Cash_Forecast_12M!C7*0.8*0.9875*0.95 -> 1.0712183e+08 | D8: =Cash_Forecast_12M!E7*0.8 -> 75363526 | E8: =Cash_Forecast_12M!F7 -> 26250720 | F8: =SUM(Loans!$G$2:$G$4) -> 5580000 | G8: =Cash_Forecast_12M!H7 -> 9400000 | H8: =Cash_Forecast_12M!I7 -> 0 | I8: =D8+E8+F8+G8+H8 -> 1.1659425e+08 | J8: =C8-I8 -> -9472416 | K8: =B8+J8 -> -4556337.1
A9: 2026-04 | B9: =K8 -> -4556337.1 | C9: =Cash_Forecast_12M!C8*0.8*0.9875*0.95 -> 1.0979988e+08 | D9: =Cash_Forecast_12M!E8*0.8 -> 77247614 | E9: =Cash_Forecast_12M!F8 -> 26565729 | F9: =SUM(Loans!$G$2:$G$4) -> 5580000 | G9: =Cash_Forecast_12M!H8 -> 0 | H9: =Cash_Forecast_12M!I8 -> 0 | I9: =D9+E9+F9+G9+H9 -> 1.0939334e+08 | J9: =C9-I9 -> 406532.99 | K9: =B9+J9 -> -4149804.1
A10: 2026-05 | B10: =K9 -> -4149804.1 | C10: =Cash_Forecast_12M!C9*0.8*0.9875*0.95 -> 1.1254487e+08 | D10: =Cash_Forecast_12M!E9*0.8 -> 79178804 | E10: =Cash_Forecast_12M!F9 -> 26884517 | F10: =SUM(Loans!$G$2:$G$4) -> 5580000 | G10: =Cash_Forecast_12M!H9 -> 0 | H10: =Cash_Forecast_12M!I9 -> 0 | I10: =D10+E10+F10+G10+H10 -> 1.1164332e+08 | J10: =C10-I10 -> 901550.78 | K10: =B10+J10 -> -3248253.3
A11: 2026-06 | B11: =K10 -> -3248253.3 | C11: =Cash_Forecast_12M!C10*0.8*0.9875*0.95 -> 1.1535849e+08 | D11: =Cash_Forecast_12M!E10*0.8 -> 81158274 | E11: =Cash_Forecast_12M!F10 -> 27207131 | F11: =SUM(Loans!$G$2:$G$4) -> 5580000 | G11: =Cash_Forecast_12M!H10 -> 28000000 | H11: =Cash_Forecast_12M!I10 -> 0 | I11: =D11+E11+F11+G11+H11 -> 1.4194541e+08 | J11: =C11-I11 -> -26586912 | K11: =B11+J11 -> -29835165
A12: 2026-07 | B12: =K11 -> -29835165 | C12: =Cash_Forecast_12M!C11*0.8*0.9875*0.95 -> 1.1824246e+08 | D12: =Cash_Forecast_12M!E11*0.8 -> 83187231 | E12: =Cash_Forecast_12M!F11 -> 27533617 | F12: =SUM(Loans!$G$2:$G$4) -> 5580000 | G12: =Cash_Forecast_12M!H11 -> 0 | H12: =Cash_Forecast_12M!I11 -> 0 | I12: =D12+E12+F12+G12+H12 -> 1.1630085e+08 | J12: =C12-I12 -> 1941608.2 | K12: =B12+J12 -> -27893557
A13: 2026-08 | B13: =K12 -> -27893557 | C13: =Cash_Forecast_12M!C12*0.8*0.9875*0.95 -> 1.2119852e+08 | D13: =Cash_Forecast_12M!E12*0.8 -> 85266912 | E13: =Cash_Forecast_12M!F12 -> 27864020 | F13: =SUM(Loans!$G$2:$G$4) -> 5580000 | G13: =Cash_Forecast_12M!H12 -> 0 | H13: =Cash_Forecast_12M!I12 -> 0 | I13: =D13+E13+F13+G13+H13 -> 1.1871093e+08 | J13: =C13-I13 -> 2487585.4 | K13: =B13+J13 -> -25405971
A14: 2026-09 | B14: =K13 -> -25405971 | C14: =Cash_Forecast_12M!C13*0.8*0.9875*0.95 -> 1.2422848e+08 | D14: =Cash_Forecast_12M!E13*0.8 -> 87398585 | E14: =Cash_Forecast_12M!F13 -> 28198389 | F14: =SUM(Loans!$G$2:$G$4) -> 5580000 | G14: =Cash_Forecast_12M!H13 -> 0 | H14: =Cash_Forecast_12M!I13 -> 0 | I14: =D14+E14+F14+G14+H14 -> 1.2117697e+08 | J14: =C14-I14 -> 3051507.3 | K14: =B14+J14 -> -22354464
A17: BEST CASE SCENARIO
A18: Month | B18: Opening Cash | C18: Best-Case Collections | D18: Equity / Financing Inflow | E18: COGS | F18: OpEx | G18: Loan Payments | H18: CapEx | I18: Tax Payments | J18: Total Outflows | K18: Net Cash Flow | L18: Closing Cash
A19: 2025-10 | B19: =Cash_Forecast_12M!B2 -> 122990111 | C19: =(Cash_Forecast_12M!C2*0.8*0.9875*0.95)-18400000 -> 76280088 | D19: 0 | E19: =Cash_Forecast_12M!E2*0.8 -> 66610375 | F19: =Cash_Forecast_12M!F2 -> 24730828 | G19: =SUM(Loans!$G$2:$G$4) -> 5580000 | H19: =Cash_Forecast_12M!H2 -> 14000000 | I19: =Cash_Forecast_12M!I2 -> 6760000 | J19: =E19+F19+G19+H19+I19 -> 1.176812e+08 | K19: =C19+D19-J19 -> -41401115 | L19: =B19+K19 -> 81588996
A20: 2025-11 | B20: =L19 -> 81588996 | C20: =(Cash_Forecast_12M!C3*0.8*0.9875*0.95)-18400000 -> 78647091 | D20: 0 | E20: =Cash_Forecast_12M!E3*0.8 -> 68275635 | F20: =Cash_Forecast_12M!F3 -> 25027598 | G20: =SUM(Loans!$G$2:$G$4) -> 5580000 | H20: =Cash_Forecast_12M!H3 -> 6800000 | I20: =Cash_Forecast_12M!I3 -> 6300000 | J20: =E20+F20+G20+H20+I20 -> 1.1198323e+08 | K20: =C20+D20-J20 -> -33336142 | L20: =B20+K20 -> 48252854
A21: 2025-12 | B21: =L20 -> 48252854 | C21: =Cash_Forecast_12M!C4*0.8*0.9875*0.95 -> 99473268 | D21: 0 | E21: =Cash_Forecast_12M!E4*0.8 -> 69982526 | F21: =Cash_Forecast_12M!F4 -> 25327929 | G21: =SUM(Loans!$G$2:$G$4) -> 5580000 | H21: =Cash_Forecast_12M!H4 -> 0 | I21: =Cash_Forecast_12M!I4 -> 18400000 | J21: =E21+F21+G21+H21+I21 -> 1.1929045e+08 | K21: =C21+D21-J21 -> -19817187 | L21: =B21+K21 -> 28435668
A22: 2026-01 | B22: =L21 -> 28435668 | C22: =Cash_Forecast_12M!C5*0.8*0.9875*0.95 -> 1.019601e+08 | D22: =400000000 -> 400000000 | E22: =Cash_Forecast_12M!E5*0.8 -> 71732089 | F22: =Cash_Forecast_12M!F5 -> 25631864 | G22: =SUM(Loans!$G$2:$G$4) -> 5580000 | H22: =Cash_Forecast_12M!H5 -> 22000000 | I22: =Cash_Forecast_12M!I5 -> 0 | J22: =E22+F22+G22+H22+I22 -> 1.2494395e+08 | K22: =C22+D22-J22 -> 3.7701615e+08 | L22: =B22+K22 -> 4.0545181e+08
A23: 2026-02 | B23: =L22 -> 4.0545181e+08 | C23: =Cash_Forecast_12M!C6*0.8*0.9875*0.95 -> 1.045091e+08 | D23: 0 | E23: =Cash_Forecast_12M!E6*0.8 -> 73525391 | F23: =Cash_Forecast_12M!F6 -> 25939447 | G23: =SUM(Loans!$G$2:$G$4) -> 5580000 | H23: =Cash_Forecast_12M!H6 -> 0 | I23: =Cash_Forecast_12M!I6 -> 0 | J23: =E23+F23+G23+H23+I23 -> 1.0504484e+08 | K23: =C23+D23-J23 -> -535735.39 | L23: =B23+K23 -> 4.0491608e+08
A24: 2026-03 | B24: =L23 -> 4.0491608e+08 | C24: =Cash_Forecast_12M!C7*0.8*0.9875*0.95 -> 1.0712183e+08 | D24: 0 | E24: =Cash_Forecast_12M!E7*0.8 -> 75363526 | F24: =Cash_Forecast_12M!F7 -> 26250720 | G24: =SUM(Loans!$G$2:$G$4) -> 5580000 | H24: =Cash_Forecast_12M!H7 -> 9400000 | I24: =Cash_Forecast_12M!I7 -> 0 | J24: =E24+F24+G24+H24+I24 -> 1.1659425e+08 | K24: =C24+D24-J24 -> -9472416 | L24: =B24+K24 -> 3.9544366e+08
A25: 2026-04 | B25: =L24 -> 3.9544366e+08 | C25: =Cash_Forecast_12M!C8*0.8*0.9875*0.95 -> 1.0979988e+08 | D25: 0 | E25: =Cash_Forecast_12M!E8*0.8 -> 77247614 | F25: =Cash_Forecast_12M!F8 -> 26565729 | G25: =SUM(Loans!$G$2:$G$4) -> 5580000 | H25: =Cash_Forecast_12M!H8 -> 0 | I25: =Cash_Forecast_12M!I8 -> 0 | J25: =E25+F25+G25+H25+I25 -> 1.0939334e+08 | K25: =C25+D25-J25 -> 406532.99 | L25: =B25+K25 -> 3.958502e+08
A26: 2026-05 | B26: =L25 -> 3.958502e+08 | C26: =Cash_Forecast_12M!C9*0.8*0.9875*0.95 -> 1.1254487e+08 | D26: 0 | E26: =Cash_Forecast_12M!E9*0.8 -> 79178804 | F26: =Cash_Forecast_12M!F9 -> 26884517 | G26: =SUM(Loans!$G$2:$G$4) -> 5580000 | H26: =Cash_Forecast_12M!H9 -> 0 | I26: =Cash_Forecast_12M!I9 -> 0 | J26: =E26+F26+G26+H26+I26 -> 1.1164332e+08 | K26: =C26+D26-J26 -> 901550.78 | L26: =B26+K26 -> 3.9675175e+08
A27: 2026-06 | B27: =L26 -> 3.9675175e+08 | C27: =Cash_Forecast_12M!C10*0.8*0.9875*0.95 -> 1.1535849e+08 | D27: 0 | E27: =Cash_Forecast_12M!E10*0.8 -> 81158274 | F27: =Cash_Forecast_12M!F10 -> 27207131 | G27: =SUM(Loans!$G$2:$G$4) -> 5580000 | H27: =Cash_Forecast_12M!H10 -> 28000000 | I27: =Cash_Forecast_12M!I10 -> 0 | J27: =E27+F27+G27+H27+I27 -> 1.4194541e+08 | K27: =C27+D27-J27 -> -26586912 | L27: =B27+K27 -> 3.7016483e+08
A28: 2026-07 | B28: =L27 -> 3.7016483e+08 | C28: =Cash_Forecast_12M!C11*0.8*0.9875*0.95 -> 1.1824246e+08 | D28: 0 | E28: =Cash_Forecast_12M!E11*0.8 -> 83187231 | F28: =Cash_Forecast_12M!F11 -> 27533617 | G28: =SUM(Loans!$G$2:$G$4) -> 5580000 | H28: =Cash_Forecast_12M!H11 -> 0 | I28: =Cash_Forecast_12M!I11 -> 0 | J28: =E28+F28+G28+H28+I28 -> 1.1630085e+08 | K28: =C28+D28-J28 -> 1941608.2 | L28: =B28+K28 -> 3.7210644e+08
A29: 2026-08 | B29: =L28 -> 3.7210644e+08 | C29: =Cash_Forecast_12M!C12*0.8*0.9875*0.95 -> 1.2119852e+08 | D29: 0 | E29: =Cash_Forecast_12M!E12*0.8 -> 85266912 | F29: =Cash_Forecast_12M!F12 -> 27864020 | G29: =SUM(Loans!$G$2:$G$4) -> 5580000 | H29: =Cash_Forecast_12M!H12 -> 0 | I29: =Cash_Forecast_12M!I12 -> 0 | J29: =E29+F29+G29+H29+I29 -> 1.1871093e+08 | K29: =C29+D29-J29 -> 2487585.4 | L29: =B29+K29 -> 3.7459403e+08
A30: 2026-09 | B30: =L29 -> 3.7459403e+08 | C30: =Cash_Forecast_12M!C13*0.8*0.9875*0.95 -> 1.2422848e+08 | D30: 0 | E30: =Cash_Forecast_12M!E13*0.8 -> 87398585 | F30: =Cash_Forecast_12M!F13 -> 28198389 | G30: =SUM(Loans!$G$2:$G$4) -> 5580000 | H30: =Cash_Forecast_12M!H13 -> 0 | I30: =Cash_Forecast_12M!I13 -> 0 | J30: =E30+F30+G30+H30+I30 -> 1.2117697e+08 | K30: =C30+D30-J30 -> 3051507.3 | L30: =B30+K30 -> 3.7764554e+08
A33: SENSITIVITY ANALYSIS
A34: AR Concentration (top-3 delay 60 days) | B34: =18400000 -> 18400000 | C34: Months 1-2 immediate hit
A35: FX Exposure (15% devaluation on USD) | B35: =Cash_Forecast_12M!C2*0.45*0.15 -> 8515530.9 | C35: Ongoing every month
A36: CapEx Q4 committed (Oct + Nov) | B36: =14000000+6800000 -> 20800000 | C36: One-time, known
A37: OpEx 20% increase | B37: =Cash_Forecast_12M!F2*0.2 -> 4946165.6 | C37: Ongoing gradual

Sheet Board_View
A1: Zumi Holdings — 12-Month Cash Runway by Scenario
A3: Month | B3: Base Case | C3: Worst Case | D3: Best Case
A4: 2025-10 | B4: =Cash_Forecast_12M!L2 -> 1.0850453e+08 | C4: =Stress_Test!K3 -> 81588996 | D4: =Stress_Test!L19 -> 81588996
A5: 2025-11 | B5: =Cash_Forecast_12M!L3 -> 1.022968e+08 | C5: =Stress_Test!K4 -> 48252854 | D5: =Stress_Test!L20 -> 48252854
A6: 2025-12 | B6: =Cash_Forecast_12M!L4 -> 91426247 | C6: =Stress_Test!K5 -> 28435668 | D6: =Stress_Test!L21 -> 28435668
A7: 2026-01 | B7: =Cash_Forecast_12M!L5 -> 77612690 | C7: =Stress_Test!K6 -> 5451814.3 | D7: =Stress_Test!L22 -> 4.0545181e+08
A8: 2026-02 | B8: =Cash_Forecast_12M!L6 -> 86476507 | C8: =Stress_Test!K7 -> 4916078.9 | D8: =Stress_Test!L23 -> 4.0491608e+08
A9: 2026-03 | B9: =Cash_Forecast_12M!L7 -> 86638633 | C9: =Stress_Test!K8 -> -4556337.1 | D9: =Stress_Test!L24 -> 3.9544366e+08
A10: 2026-04 | B10: =Cash_Forecast_12M!L8 -> 96920571 | C10: =Stress_Test!K9 -> -4149804.1 | D10: =Stress_Test!L25 -> 3.958502e+08
A11: 2026-05 | B11: =Cash_Forecast_12M!L9 -> 1.0794441e+08 | C11: =Stress_Test!K10 -> -3248253.3 | D11: =Stress_Test!L26 -> 3.9675175e+08
A12: 2026-06 | B12: =Cash_Forecast_12M!L10 -> 91732848 | C12: =Stress_Test!K11 -> -29835165 | D12: =Stress_Test!L27 -> 3.7016483e+08
A13: 2026-07 | B13: =Cash_Forecast_12M!L11 -> 1.0430919e+08 | C13: =Stress_Test!K12 -> -27893557 | D13: =Stress_Test!L28 -> 3.7210644e+08
A14: 2026-08 | B14: =Cash_Forecast_12M!L12 -> 1.1769737e+08 | C14: =Stress_Test!K13 -> -25405971 | D14: =Stress_Test!L29 -> 3.7459403e+08
A15: 2026-09 | B15: =Cash_Forecast_12M!L13 -> 1.3192199e+08 | C15: =Stress_Test!K14 -> -22354464 | D15: =Stress_Test!L30 -> 3.7764554e+08
A18: BASE CASE RUNWAY | B18: =Runway!D10 -> 12+ months — cash stays positive
A19: WORST CASE RUNWAY | B19: =Runway!D12 -> 6
A20: BEST CASE RUNWAY | B20: =Runway!D14 -> 12+ months — cash stays positive
A22: Zumi Holdings — Cash Runway Summary With ₦142M in the bank, Zumi is stable under normal conditions, the base case confirms 12+ months of runway, with closing cash growing to ₦131.9M by September 2026. The risk is concentrated, not spread. Three customers — Dangote Group, MTN Nigeria, and Flutterwave, holds 62% of outstanding receivables (₦18.4M). If they delay simultaneously alongside a 15% FX devaluation and a 20% revenue drop, cash turns negative in December 2025 which is just 3 months of safe runway. The December ₦18.4M CIT instalment is what finishes it. On the upside, drawing the ₦400M Series A in January 2026 extends closing cash to ₦584M by year-end. Three actions the board must approve: Reduce top-3 AR concentration below 45% immediately Secure a committed credit facility before Q4 capex hits (₦20.8M committed in Oct–Nov) Ring-fence the Bento Africa payroll (₦12.4M/month), this is the one AP obligation that cannot slip. The base case is fine. The worst case is December. That is the number that matters.
