Workbook

Sheet README
A1: Zumi Holdings — Q3 2025 Group Ledger
A3: ## Your assignment
A4: You are the new analyst. The CFO dropped this raw export on your desk Friday at 5pm and wants a clean Q3 P&L by Monday 9am. By brand. By month. With variance commentary.
A6: ## What you have
A7: Tab 'Raw_Ledger' has 1,200+ entries pulled from three different systems (POS, accounting, payroll). It is messy on purpose. Real exports are.
A8: Tab 'Chart_of_Accounts' is the official mapping. Use it.
A9: Tab 'FX_Rates' has month-end NGN rates for USD and GHS entries.
A10: Tab 'Bank_Statements' is the source of truth for cash. Reconcile against the ledger.
A12: ## What you must build
A13: 1. 'Cleaned' tab. One row per transaction, NGN-normalized, properly categorized. Use formulas, not paste-values.
A14: 2. 'PL_By_Brand_Month' tab. Revenue / COGS / Gross Profit / Opex / EBITDA. Brand x Month matrix.
A15: 3. 'Reconciliation' tab. Reconcile Cleaned to Bank_Statements. Flag every variance over NGN 50,000.
... A24: When you write commentary, write like you mean it. Short sentences. Specific numbers. No fluff. The CEO hates fluff.

Sheet tbl_Bank
A1: Month | B1: Bank_Account | C1: Currency | D1: Total_Inflow | E1: Total_Outflow | F1: Net_Movement | G1: Notes
A2: 2025-07 | B2: GTB - NGN Operating | C2: NGN | D2: 132840000 | E2: -98120000 | F2: 34720000
A3: 2025-07 | B3: GTB - USD Domiciliary | C3: USD | D3: 14820 | E3: -1460 | F3: 13360 | G3: Logistics + ads
A4: 2025-08 | B4: GTB - NGN Operating | C4: NGN | D4: 141980000 | E4: -106410000 | F4: 35570000 | G4: Includes duplicate vendor pmt
A5: 2025-08 | B5: GTB - USD Domiciliary | C5: USD | D5: 16320 | E5: -1640 | F5: 14680
A6: 2025-09 | B6: GTB - NGN Operating | C6: NGN | D6: 152410000 | E6: -109840000 | F6: 42570000
A7: 2025-09 | B7: GTB - USD Domiciliary | C7: USD | D7: 18940 | E7: -1710 | F7: 17230

Sheet tbl_Accounts
A1: Account_Code | B1: Account_Name | C1: Type | D1: PL_Bucket
A2: 4000 | B2: Order Revenue | C2: Revenue | D2: Revenue
A3: 4010 | B3: Subscription Revenue | C3: Revenue | D3: Revenue
A4: 4020 | B4: Logistics Contract Revenue | C4: Revenue | D4: Revenue
A5: 4900 | B5: Refunds & Chargebacks | C5: Revenue | D5: Revenue
A6: 5000 | B6: Food Cost | C6: COGS | D6: COGS
A7: 5010 | B7: Inventory Purchases | C7: COGS | D7: COGS
A8: 5020 | B8: Packaging | C8: COGS | D8: COGS
A9: 5030 | B9: Fuel & Vehicle | C9: COGS | D9: COGS
A10: 5040 | B10: Rider Payouts | C10: COGS | D10: COGS
A11: 5050 | B11: Aggregator Commission | C11: COGS | D11: COGS
A12: 6000 | B12: Salaries & Wages | C12: Opex | D12: Opex
... A21: 6900 | B21: Other / Uncategorized | C21: Opex | D21: Opex

Sheet tbl_FX
A1: Month | B1: Currency | C1: Rate_to_NGN | D1: Key
A2: 2025-07 | B2: NGN | C2: 1 | D2: =tbl_FX[[#This Row],[Month]] & tbl_FX[[#This Row],[Currency]] -> 2025-07NGN
A3: 2025-07 | B3: USD | C3: 1530 | D3: =tbl_FX[[#This Row],[Month]] & tbl_FX[[#This Row],[Currency]] -> 2025-07USD
A4: 2025-07 | B4: GHS | C4: 102 | D4: =tbl_FX[[#This Row],[Month]] & tbl_FX[[#This Row],[Currency]] -> 2025-07GHS
A5: 2025-08 | B5: NGN | C5: 1 | D5: =tbl_FX[[#This Row],[Month]] & tbl_FX[[#This Row],[Currency]] -> 2025-08NGN
A6: 2025-08 | B6: USD | C6: 1572 | D6: =tbl_FX[[#This Row],[Month]] & tbl_FX[[#This Row],[Currency]] -> 2025-08USD
A7: 2025-08 | B7: GHS | C7: 99 | D7: =tbl_FX[[#This Row],[Month]] & tbl_FX[[#This Row],[Currency]] -> 2025-08GHS
A8: 2025-09 | B8: NGN | C8: 1 | D8: =tbl_FX[[#This Row],[Month]] & tbl_FX[[#This Row],[Currency]] -> 2025-09NGN
A9: 2025-09 | B9: USD | C9: 1611 | D9: =tbl_FX[[#This Row],[Month]] & tbl_FX[[#This Row],[Currency]] -> 2025-09USD
A10: 2025-09 | B10: GHS | C10: 96 | D10: =tbl_FX[[#This Row],[Month]] & tbl_FX[[#This Row],[Currency]] -> 2025-09GHS

Sheet tbl_Ledger
A1: Txn_ID | B1: Date | C1: Source_System | D1: Brand | E1: Channel | F1: Account_Code | G1: Account_Name | H1: Description | I1: Currency | J1: Amount | K1: Vendor_or_Customer | L1: Reference | M1: Notes | N1: Month | O1: Key | P1: Rate_to_NGN | Q1: Adjusted_Amount_NGN | R1: Account_Type | S1: PL_Bucket | T1: Clean_Amount
A2: T101434 | B2: 45839 | C2: QuickBooks | D2: Zumi Logistics | F2: 5030 | G2: Fuel & Vehicle | H2: Fuel top-up — invoice missing date | I2: NGN | J2: -240000 | K2: NNPC Retail | L2: BILL-NODATE | N2: =TEXT(tbl_Ledger[[#This Row],[Date]],"yyyy-mm") -> 2025-07 | O2: =TEXT(tbl_Ledger[[#This Row],[Date]],"yyyy-mm") & TRIM(tbl_Ledger[[#This Row],[Currency]]) -> 2025-07NGN | P2: =_xlfn.XLOOKUP(tbl_Ledger[[#This Row],[Key]], tbl_FX[Key], tbl_FX[Rate_to_NGN]) -> 1 | Q2: =IF(tbl_Ledger[[#This Row],[Account_Type]]="Expense",-ABS(tbl_Ledger[[#This Row],[Amount]]*tbl_Ledger[[#This Row],[Rate_to_NGN]]),tbl_Ledger[[#This Row],[Amount]]*tbl_Ledger[[#This Row],[Rate_to_NGN]]) -> -240000 | R2: =_xlfn.XLOOKUP(tbl_Ledger[[#This Row],[Account_Code]], tbl_Accounts[Account_Code], tbl_Accounts[Type]) -> COGS | S2: =_xlfn.XLOOKUP(tbl_Ledger[[#This Row],[Account_Code]], tbl_Accounts[Account_Code], tbl_Accounts[PL_Bucket]) -> COGS | T2: =IF(AND(S2="Revenue",F2<>4900),ABS(Q2),-ABS(Q2)) -> -240000
A3: T100001 | B3: 45839 | C3: POS-Square | D3: Zumi Eats | E3: Mobile App | F3: 4000 | G3: Order Revenue | H3: Mobile App daily settlement 2025-07-01 | I3: NGN | J3: 27600 | L3: INV-20250701-MOB | N3: =TEXT(tbl_Ledger[[#This Row],[Date]],"yyyy-mm") -> 2025-07 | O3: =TEXT(tbl_Ledger[[#This Row],[Date]],"yyyy-mm") & TRIM(tbl_Ledger[[#This Row],[Currency]]) -> 2025-07NGN | P3: =_xlfn.XLOOKUP(tbl_Ledger[[#This Row],[Key]], tbl_FX[Key], tbl_FX[Rate_to_NGN]) -> 1 | Q3: =IF(tbl_Ledger[[#This Row],[Account_Type]]="Expense",-ABS(tbl_Ledger[[#This Row],[Amount]]*tbl_Ledger[[#This Row],[Rate_to_NGN]]),tbl_Ledger[[#This Row],[Amount]]*tbl_Ledger[[#This Row],[Rate_to_NGN]]) -> 27600 | R3: =_xlfn.XLOOKUP(tbl_Ledger[[#This Row],[Account_Code]], tbl_Accounts[Account_Code], tbl_Accounts[Type]) -> Revenue | S3: =_xlfn.XLOOKUP(tbl_Ledger[[#This Row],[Account_Code]], tbl_Accounts[Account_Code], tbl_Accounts[PL_Bucket]) -> Revenue | T3: =IF(AND(S3="Revenue",F3<>4900),ABS(Q3),-ABS(Q3)) -> 27600
A4: T100002 | B4: 45839 | C4: POS-Square | D4: Zumi Eats | E4: Website | F4: 4000 | G4: Order Revenue | H4: Website daily settlement 2025-07-01 | I4: NGN | J4: 29800 | L4: INV-20250701-WEB | N4: =TEXT(tbl_Ledger[[#This Row],[Date]],"yyyy-mm") -> 2025-07 | O4: =TEXT(tbl_Ledger[[#This Row],[Date]],"yyyy-mm") & TRIM(tbl_Ledger[[#This Row],[Currency]]) -> 2025-07NGN | P4: =_xlfn.XLOOKUP(tbl_Ledger[[#This Row],[Key]], tbl_FX[Key], tbl_FX[Rate_to_NGN]) -> 1 | Q4: =IF(tbl_Ledger[[#This Row],[Account_Type]]="Expense",-ABS(tbl_Ledger[[#This Row],[Amount]]*tbl_Ledger[[#This Row],[Rate_to_NGN]]),tbl_Ledger[[#This Row],[Amount]]*tbl_Ledger[[#This Row],[Rate_to_NGN]]) -> 29800 | R4: =_xlfn.XLOOKUP(tbl_Ledger[[#This Row],[Account_Code]], tbl_Accounts[Account_Code], tbl_Accounts[Type]) -> Revenue | S4: =_xlfn.XLOOKUP(tbl_Ledger[[#This Row],[Account_Code]], tbl_Accounts[Account_Code], tbl_Accounts[PL_Bucket]) -> Revenue | T4: =IF(AND(S4="Revenue",F4<>4900),ABS(Q4),-ABS(Q4)) -> 29800
A5: T100003 | B5: 45839 | C5: POS-Square | D5: Zumi Eats | E5: Aggregator-Glovo | F5: 4000 | G5: Order Revenue | H5: Aggregator-Glovo daily settlement 2025-07-01 | I5: NGN | J5: 29500 | L5: INV-20250701-AGG | N5: =TEXT(tbl_Ledger[[#This Row],[Date]],"yyyy-mm") -> 2025-07 | O5: =TEXT(tbl_Ledger[[#This Row],[Date]],"yyyy-mm") & TRIM(tbl_Ledger[[#This Row],[Currency]]) -> 2025-07NGN | P5: =_xlfn.XLOOKUP(tbl_Ledger[[#This Row],[Key]], tbl_FX[Key], tbl_FX[Rate_to_NGN]) -> 1 | Q5: =IF(tbl_Ledger[[#This Row],[Account_Type]]="Expense",-ABS(tbl_Ledger[[#This Row],[Amount]]*tbl_Ledger[[#This Row],[Rate_to_NGN]]),tbl_Ledger[[#This Row],[Amount]]*tbl_Ledger[[#This Row],[Rate_to_NGN]]) -> 29500 | R5: =_xlfn.XLOOKUP(tbl_Ledger[[#This Row],[Account_Code]], tbl_Accounts[Account_Code], tbl_Accounts[Type]) -> Revenue | S5: =_xlfn.XLOOKUP(tbl_Ledger[[#This Row],[Account_Code]], tbl_Accounts[Account_Code], tbl_Accounts[PL_Bucket]) -> Revenue | T5: =IF(AND(S5="Revenue",F5<>4900),ABS(Q5),-ABS(Q5)) -> 29500
A6: T100004 | B6: 45839 | C6: POS-Square | D6: Zumi Eats | E6: Walk-in | F6: 4000 | G6: Order Revenue | H6: Walk-in daily settlement 2025-07-01 | I6: NGN | J6: 31400 | L6: INV-20250701-WAL | N6: =TEXT(tbl_Ledger[[#This Row],[Date]],"yyyy-mm") -> 2025-07 | O6: =TEXT(tbl_Ledger[[#This Row],[Date]],"yyyy-mm") & TRIM(tbl_Ledger[[#This Row],[Currency]]) -> 2025-07NGN | P6: =_xlfn.XLOOKUP(tbl_Ledger[[#This Row],[Key]], tbl_FX[Key], tbl_FX[Rate_to_NGN]) -> 1 | Q6: =IF(tbl_Ledger[[#This Row],[Account_Type]]="Expense",-ABS(tbl_Ledger[[#This Row],[Amount]]*tbl_Ledger[[#This Row],[Rate_to_NGN]]),tbl_Ledger[[#This Row],[Amount]]*tbl_Ledger[[#This Row],[Rate_to_NGN]]) -> 31400 | R6: =_xlfn.XLOOKUP(tbl_Ledger[[#This Row],[Account_Code]], tbl_Accounts[Account_Code], tbl_Accounts[Type]) -> Revenue | S6: =_xlfn.XLOOKUP(tbl_Ledger[[#This Row],[Account_Code]], tbl_Accounts[Account_Code], tbl_Accounts[PL_Bucket]) -> Revenue | T6: =IF(AND(S6="Revenue",F6<>4900),ABS(Q6),-ABS(Q6)) -> 31400
A7: T100005 | B7: 45839 | C7: POS-Square | D7: Zumi Mart | E7: POS-Lekki | F7: 4000 | G7: Order Revenue | H7: POS-Lekki daily settlement 2025-07-01 | I7: NGN | J7: 48600 | L7: INV-20250701-POS | N7: =TEXT(tbl_Ledger[[#This Row],[Date]],"yyyy-mm") -> 2025-07 | O7: =TEXT(tbl_Ledger[[#This Row],[Date]],"yyyy-mm") & TRIM(tbl_Ledger[[#This Row],[Currency]]) -> 2025-07NGN | P7: =_xlfn.XLOOKUP(tbl_Ledger[[#This Row],[Key]], tbl_FX[Key], tbl_FX[Rate_to_NGN]) -> 1 | Q7: =IF(tbl_Ledger[[#This Row],[Account_Type]]="Expense",-ABS(tbl_Ledger[[#This Row],[Amount]]*tbl_Ledger[[#This Row],[Rate_to_NGN]]),tbl_Ledger[[#This Row],[Amount]]*tbl_Ledger[[#This Row],[Rate_to_NGN]]) -> 48600 | R7: =_xlfn.XLOOKUP(tbl_Ledger[[#This Row],[Account_Code]], tbl_Accounts[Account_Code], tbl_Accounts[Type]) -> Revenue | S7: =_xlfn.XLOOKUP(tbl_Ledger[[#This Row],[Account_Code]], tbl_Accounts[Account_Code], tbl_Accounts[PL_Bucket]) -> Revenue | T7: =IF(AND(S7="Revenue",F7<>4900),ABS(Q7),-ABS(Q7)) -> 48600
A8: T100006 | B8: 45839 | C8: POS-Square | D8: Zumi Mart | E8: POS-VI | F8: 4000 | G8: Order Revenue | H8: POS-VI daily settlement 2025-07-01 | I8: NGN | J8: 45700 | L8: INV-20250701-POS | N8: =TEXT(tbl_Ledger[[#This Row],[Date]],"yyyy-mm") -> 2025-07 | O8: =TEXT(tbl_Ledger[[#This Row],[Date]],"yyyy-mm") & TRIM(tbl_Ledger[[#This Row],[Currency]]) -> 2025-07NGN | P8: =_xlfn.XLOOKUP(tbl_Ledger[[#This Row],[Key]], tbl_FX[Key], tbl_FX[Rate_to_NGN]) -> 1 | Q8: =IF(tbl_Ledger[[#This Row],[Account_Type]]="Expense",-ABS(tbl_Ledger[[#This Row],[Amount]]*tbl_Ledger[[#This Row],[Rate_to_NGN]]),tbl_Ledger[[#This Row],[Amount]]*tbl_Ledger[[#This Row],[Rate_to_NGN]]) -> 45700 | R8: =_xlfn.XLOOKUP(tbl_Ledger[[#This Row],[Account_Code]], tbl_Accounts[Account_Code], tbl_Accounts[Type]) -> Revenue | S8: =_xlfn.XLOOKUP(tbl_Ledger[[#This Row],[Account_Code]], tbl_Accounts[Account_Code], tbl_Accounts[PL_Bucket]) -> Revenue | T8: =IF(AND(S8="Revenue",F8<>4900),ABS(Q8),-ABS(Q8)) -> 45700
A9: T100007 | B9: 45839 | C9: POS-Square | D9: Zumi Mart | E9: POS-Ikeja | F9: 4000 | G9: Order Revenue | H9: POS-Ikeja daily settlement 2025-07-01 | I9: NGN | J9: 46300 | L9: INV-20250701-POS | N9: =TEXT(tbl_Ledger[[#This Row],[Date]],"yyyy-mm") -> 2025-07 | O9: =TEXT(tbl_Ledger[[#This Row],[Date]],"yyyy-mm") & TRIM(tbl_Ledger[[#This Row],[Currency]]) -> 2025-07NGN | P9: =_xlfn.XLOOKUP(tbl_Ledger[[#This Row],[Key]], tbl_FX[Key], tbl_FX[Rate_to_NGN]) -> 1 | Q9: =IF(tbl_Ledger[[#This Row],[Account_Type]]="Expense",-ABS(tbl_Ledger[[#This Row],[Amount]]*tbl_Ledger[[#This Row],[Rate_to_NGN]]),tbl_Ledger[[#This Row],[Amount]]*tbl_Ledger[[#This Row],[Rate_to_NGN]]) -> 46300 | R9: =_xlfn.XLOOKUP(tbl_Ledger[[#This Row],[Account_Code]], tbl_Accounts[Account_Code], tbl_Accounts[Type]) -> Revenue | S9: =_xlfn.XLOOKUP(tbl_Ledger[[#This Row],[Account_Code]], tbl_Accounts[Account_Code], tbl_Accounts[PL_Bucket]) -> Revenue | T9: =IF(AND(S9="Revenue",F9<>4900),ABS(Q9),-ABS(Q9)) -> 46300
A10: T100008 | B10: 45839 | C10: POS-Square | D10: Zumi Mart | E10: Online | F10: 4000 | G10: Order Revenue | H10: Online daily settlement 2025-07-01 | I10: NGN | J10: 49000 | L10: INV-20250701-ONL | N10: =TEXT(tbl_Ledger[[#This Row],[Date]],"yyyy-mm") -> 2025-07 | O10: =TEXT(tbl_Ledger[[#This Row],[Date]],"yyyy-mm") & TRIM(tbl_Ledger[[#This Row],[Currency]]) -> 2025-07NGN | P10: =_xlfn.XLOOKUP(tbl_Ledger[[#This Row],[Key]], tbl_FX[Key], tbl_FX[Rate_to_NGN]) -> 1 | Q10: =IF(tbl_Ledger[[#This Row],[Account_Type]]="Expense",-ABS(tbl_Ledger[[#This Row],[Amount]]*tbl_Ledger[[#This Row],[Rate_to_NGN]]),tbl_Ledger[[#This Row],[Amount]]*tbl_Ledger[[#This Row],[Rate_to_NGN]]) -> 49000 | R10: =_xlfn.XLOOKUP(tbl_Ledger[[#This Row],[Account_Code]], tbl_Accounts[Account_Code], tbl_Accounts[Type]) -> Revenue | S10: =_xlfn.XLOOKUP(tbl_Ledger[[#This Row],[Account_Code]], tbl_Accounts[Account_Code], tbl_Accounts[PL_Bucket]) -> Revenue | T10: =IF(AND(S10="Revenue",F10<>4900),ABS(Q10),-ABS(Q10)) -> 49000
A11: T100009 | B11: 45839 | C11: NetSuite | D11: Zumi Logistics | E11: Contract-Dangote | F11: 4020 | G11: Logistics Contract Revenue | H11: Contract-Dangote daily settlement 2025-07-01 | I11: NGN | J11: 41900 | K11: Dangote | L11: INV-20250701-CON | N11: =TEXT(tbl_Ledger[[#This Row],[Date]],"yyyy-mm") -> 2025-07 | O11: =TEXT(tbl_Ledger[[#This Row],[Date]],"yyyy-mm") & TRIM(tbl_Ledger[[#This Row],[Currency]]) -> 2025-07NGN | P11: =_xlfn.XLOOKUP(tbl_Ledger[[#This Row],[Key]], tbl_FX[Key], tbl_FX[Rate_to_NGN]) -> 1 | Q11: =IF(tbl_Ledger[[#This Row],[Account_Type]]="Expense",-ABS(tbl_Ledger[[#This Row],[Amount]]*tbl_Ledger[[#This Row],[Rate_to_NGN]]),tbl_Ledger[[#This Row],[Amount]]*tbl_Ledger[[#This Row],[Rate_to_NGN]]) -> 41900 | R11: =_xlfn.XLOOKUP(tbl_Ledger[[#This Row],[Account_Code]], tbl_Accounts[Account_Code], tbl_Accounts[Type]) -> Revenue | S11: =_xlfn.XLOOKUP(tbl_Ledger[[#This Row],[Account_Code]], tbl_Accounts[Account_Code], tbl_Accounts[PL_Bucket]) -> Revenue | T11: =IF(AND(S11="Revenue",F11<>4900),ABS(Q11),-ABS(Q11)) -> 41900
A12: T100010 | B12: 45839 | C12: NetSuite | D12: Zumi Logistics | E12: Contract-MTN | F12: 4020 | G12: Logistics Contract Revenue | H12: Contract-MTN daily settlement 2025-07-01 | I12: USD | J12: 28.04 | K12: MTN | L12: INV-20250701-CON | N12: =TEXT(tbl_Ledger[[#This Row],[Date]],"yyyy-mm") -> 2025-07 | O12: =TEXT(tbl_Ledger[[#This Row],[Date]],"yyyy-mm") & TRIM(tbl_Ledger[[#This Row],[Currency]]) -> 2025-07USD | P12: =_xlfn.XLOOKUP(tbl_Ledger[[#This Row],[Key]], tbl_FX[Key], tbl_FX[Rate_to_NGN]) -> 1530 | Q12: =IF(tbl_Ledger[[#This Row],[Account_Type]]="Expense",-ABS(tbl_Ledger[[#This Row],[Amount]]*tbl_Ledger[[#This Row],[Rate_to_NGN]]),tbl_Ledger[[#This Row],[Amount]]*tbl_Ledger[[#This Row],[Rate_to_NGN]]) -> 42901.2 | R12: =_xlfn.XLOOKUP(tbl_Ledger[[#This Row],[Account_Code]], tbl_Accounts[Account_Code], tbl_Accounts[Type]) -> Revenue | S12: =_xlfn.XLOOKUP(tbl_Ledger[[#This Row],[Account_Code]], tbl_Accounts[Account_Code], tbl_Accounts[PL_Bucket]) -> Revenue | T12: =IF(AND(S12="Revenue",F12<>4900),ABS(Q12),-ABS(Q12)) -> 42901.2
A13: T100011 | B13: 45839 | C13: NetSuite | D13: Zumi Logistics | E13: Contract-Flutterwave | F13: 4020 | G13: Logistics Contract Revenue | H13: Contract-Flutterwave daily settlement 2025-07-01 | I13: USD | J13: 28.95 | K13: Flutterwave | L13: INV-20250701-CON | N13: =TEXT(tbl_Ledger[[#This Row],[Date]],"yyyy-mm") -> 2025-07 | O13: =TEXT(tbl_Ledger[[#This Row],[Date]],"yyyy-mm") & TRIM(tbl_Ledger[[#This Row],[Currency]]) -> 2025-07USD | P13: =_xlfn.XLOOKUP(tbl_Ledger[[#This Row],[Key]], tbl_FX[Key], tbl_FX[Rate_to_NGN]) -> 1530 | Q13: =IF(tbl_Ledger[[#This Row],[Account_Type]]="Expense",-ABS(tbl_Ledger[[#This Row],[Amount]]*tbl_Ledger[[#This Row],[Rate_to_NGN]]),tbl_Ledger[[#This Row],[Amount]]*tbl_Ledger[[#This Row],[Rate_to_NGN]]) -> 44293.5 | R13: =_xlfn.XLOOKUP(tbl_Ledger[[#This Row],[Account_Code]], tbl_Accounts[Account_Code], tbl_Accounts[Type]) -> Revenue | S13: =_xlfn.XLOOKUP(tbl_Ledger[[#This Row],[Account_Code]], tbl_Accounts[Account_Code], tbl_Accounts[PL_Bucket]) -> Revenue | T13: =IF(AND(S13="Revenue",F13<>4900),ABS(Q13),-ABS(Q13)) -> 44293.5
A14: T100012 | B14: 45839 | C14: NetSuite | D14: Zumi Logistics | E14: Spot-Market | F14: 4020 | G14: Logistics Contract Revenue | H14: Spot-Market daily settlement 2025-07-01 | I14: NGN | J14: 47700 | L14: INV-20250701-SPO | N14: =TEXT(tbl_Ledger[[#This Row],[Date]],"yyyy-mm") -> 2025-07 | O14: =TEXT(tbl_Ledger[[#This Row],[Date]],"yyyy-mm") & TRIM(tbl_Ledger[[#This Row],[Currency]]) -> 2025-07NGN | P14: =_xlfn.XLOOKUP(tbl_Ledger[[#This Row],[Key]], tbl_FX[Key], tbl_FX[Rate_to_NGN]) -> 1 | Q14: =IF(tbl_Ledger[[#This Row],[Account_Type]]="Expense",-ABS(tbl_Ledger[[#This Row],[Amount]]*tbl_Ledger[[#This Row],[Rate_to_NGN]]),tbl_Ledger[[#This Row],[Amount]]*tbl_Ledger[[#This Row],[Rate_to_NGN]]) -> 47700 | R14: =_xlfn.XLOOKUP(tbl_Ledger[[#This Row],[Account_Code]], tbl_Accounts[Account_Code], tbl_Accounts[Type]) -> Revenue | S14: =_xlfn.XLOOKUP(tbl_Ledger[[#This Row],[Account_Code]], tbl_Accounts[Account_Code], tbl_Accounts[PL_Bucket]) -> Revenue | T14: =IF(AND(S14="Revenue",F14<>4900),ABS(Q14),-ABS(Q14)) -> 47700
A15: T101249 | B15: 45839 | C15: QuickBooks | D15: Zumi Mart | F15: 5010 | G15: Inventory Purchases | H15: Distell Wholesale invoice 2025-07 | I15: NGN | J15: -1691000 | K15: Distell Wholesale | L15: BILL-13747 | N15: =TEXT(tbl_Ledger[[#This Row],[Date]],"yyyy-mm") -> 2025-07 | O15: =TEXT(tbl_Ledger[[#This Row],[Date]],"yyyy-mm") & TRIM(tbl_Ledger[[#This Row],[Currency]]) -> 2025-07NGN | P15: =_xlfn.XLOOKUP(tbl_Ledger[[#This Row],[Key]], tbl_FX[Key], tbl_FX[Rate_to_NGN]) -> 1 | Q15: =IF(tbl_Ledger[[#This Row],[Account_Type]]="Expense",-ABS(tbl_Ledger[[#This Row],[Amount]]*tbl_Ledger[[#This Row],[Rate_to_NGN]]),tbl_Ledger[[#This Row],[Amount]]*tbl_Ledger[[#This Row],[Rate_to_NGN]]) -> -1691000 | R15: =_xlfn.XLOOKUP(tbl_Ledger[[#This Row],[Account_Code]], tbl_Accounts[Account_Code], tbl_Accounts[Type]) -> COGS | S15: =_xlfn.XLOOKUP(tbl_Ledger[[#This Row],[Account_Code]], tbl_Accounts[Account_Code], tbl_Accounts[PL_Bucket]) -> COGS | T15: =IF(AND(S15="Revenue",F15<>4900),ABS(Q15),-ABS(Q15)) -> -1691000
A16: T101265 | B16: 45839 | C16: QuickBooks | D16: Zumi Logistics | F16: 5030 | G16: Fuel & Vehicle | H16: NNPC Retail invoice 2025-07 | I16: NGN | J16: -522000 | K16: NNPC Retail | L16: BILL-18601 | N16: =TEXT(tbl_Ledger[[#This Row],[Date]],"yyyy-mm") -> 2025-07 | O16: =TEXT(tbl_Ledger[[#This Row],[Date]],"yyyy-mm") & TRIM(tbl_Ledger[[#This Row],[Currency]]) -> 2025-07NGN | P16: =_xlfn.XLOOKUP(tbl_Ledger[[#This Row],[Key]], tbl_FX[Key], tbl_FX[Rate_to_NGN]) -> 1 | Q16: =IF(tbl_Ledger[[#This Row],[Account_Type]]="Expense",-ABS(tbl_Ledger[[#This Row],[Amount]]*tbl_Ledger[[#This Row],[Rate_to_NGN]]),tbl_Ledger[[#This Row],[Amount]]*tbl_Ledger[[#This Row],[Rate_to_NGN]]) -> -522000 | R16: =_xlfn.XLOOKUP(tbl_Ledger[[#This Row],[Account_Code]], tbl_Accounts[Account_Code], tbl_Accounts[Type]) -> COGS | S16: =_xlfn.XLOOKUP(tbl_Ledger[[#This Row],[Account_Code]], tbl_Accounts[Account_Code], tbl_Accounts[PL_Bucket]) -> COGS | T16: =IF(AND(S16="Revenue",F16<>4900),ABS(Q16),-ABS(Q16)) -> -522000
A17: T100013 | B17: 45840 | C17: POS-Square | D17: Zumi Eats | E17: Mobile App | F17: 4000 | G17: Order Revenue | H17: Mobile App daily settlement 2025-07-02 | I17: NGN | J17: 31500 | L17: INV-20250702-MOB | N17: =TEXT(tbl_Ledger[[#This Row],[Date]],"yyyy-mm") -> 2025-07 | O17: =TEXT(tbl_Ledger[[#This Row],[Date]],"yyyy-mm") & TRIM(tbl_Ledger[[#This Row],[Currency]]) -> 2025-07NGN | P17: =_xlfn.XLOOKUP(tbl_Ledger[[#This Row],[Key]], tbl_FX[Key], tbl_FX[Rate_to_NGN]) -> 1 | Q17: =IF(tbl_Ledger[[#This Row],[Account_Type]]="Expense",-ABS(tbl_Ledger[[#This Row],[Amount]]*tbl_Ledger[[#This Row],[Rate_to_NGN]]),tbl_Ledger[[#This Row],[Amount]]*tbl_Ledger[[#This Row],[Rate_to_NGN]]) -> 31500 | R17: =_xlfn.XLOOKUP(tbl_Ledger[[#This Row],[Account_Code]], tbl_Accounts[Account_Code], tbl_Accounts[Type]) -> Revenue | S17: =_xlfn.XLOOKUP(tbl_Ledger[[#This Row],[Account_Code]], tbl_Accounts[Account_Code], tbl_Accounts[PL_Bucket]) -> Revenue | T17: =IF(AND(S17="Revenue",F17<>4900),ABS(Q17),-ABS(Q17)) -> 31500
A18: T100014 | B18: 45840 | C18: POS-Square | D18: Zumi Eats | E18: Website | F18: 4000 | G18: Order Revenue | H18: Website daily settlement 2025-07-02 | I18: NGN | J18: 27600 | L18: INV-20250702-WEB | N18: =TEXT(tbl_Ledger[[#This Row],[Date]],"yyyy-mm") -> 2025-07 | O18: =TEXT(tbl_Ledger[[#This Row],[Date]],"yyyy-mm") & TRIM(tbl_Ledger[[#This Row],[Currency]]) -> 2025-07NGN | P18: =_xlfn.XLOOKUP(tbl_Ledger[[#This Row],[Key]], tbl_FX[Key], tbl_FX[Rate_to_NGN]) -> 1 | Q18: =IF(tbl_Ledger[[#This Row],[Account_Type]]="Expense",-ABS(tbl_Ledger[[#This Row],[Amount]]*tbl_Ledger[[#This Row],[Rate_to_NGN]]),tbl_Ledger[[#This Row],[Amount]]*tbl_Ledger[[#This Row],[Rate_to_NGN]]) -> 27600 | R18: =_xlfn.XLOOKUP(tbl_Ledger[[#This Row],[Account_Code]], tbl_Accounts[Account_Code], tbl_Accounts[Type]) -> Revenue | S18: =_xlfn.XLOOKUP(tbl_Ledger[[#This Row],[Account_Code]], tbl_Accounts[Account_Code], tbl_Accounts[PL_Bucket]) -> Revenue | T18: =IF(AND(S18="Revenue",F18<>4900),ABS(Q18),-ABS(Q18)) -> 27600
A19: T100015 | B19: 45840 | C19: POS-Square | D19: Zumi Eats | E19: Aggregator-Glovo | F19: 4000 | G19: Order Revenue | H19: Aggregator-Glovo daily settlement 2025-07-02 | I19: NGN | J19: 27700 | L19: INV-20250702-AGG | N19: =TEXT(tbl_Ledger[[#This Row],[Date]],"yyyy-mm") -> 2025-07 | O19: =TEXT(tbl_Ledger[[#This Row],[Date]],"yyyy-mm") & TRIM(tbl_Ledger[[#This Row],[Currency]]) -> 2025-07NGN | P19: =_xlfn.XLOOKUP(tbl_Ledger[[#This Row],[Key]], tbl_FX[Key], tbl_FX[Rate_to_NGN]) -> 1 | Q19: =IF(tbl_Ledger[[#This Row],[Account_Type]]="Expense",-ABS(tbl_Ledger[[#This Row],[Amount]]*tbl_Ledger[[#This Row],[Rate_to_NGN]]),tbl_Ledger[[#This Row],[Amount]]*tbl_Ledger[[#This Row],[Rate_to_NGN]]) -> 27700 | R19: =_xlfn.XLOOKUP(tbl_Ledger[[#This Row],[Account_Code]], tbl_Accounts[Account_Code], tbl_Accounts[Type]) -> Revenue | S19: =_xlfn.XLOOKUP(tbl_Ledger[[#This Row],[Account_Code]], tbl_Accounts[Account_Code], tbl_Accounts[PL_Bucket]) -> Revenue | T19: =IF(AND(S19="Revenue",F19<>4900),ABS(Q19),-ABS(Q19)) -> 27700
A20: T100016 | B20: 45840 | C20: POS-Square | D20: Zumi Eats | E20: Aggregator-Bolt | F20: 4000 | G20: Order Revenue | H20: Aggregator-Bolt daily settlement 2025-07-02 | I20: NGN | J20: 27000 | L20: INV-20250702-AGG | N20: =TEXT(tbl_Ledger[[#This Row],[Date]],"yyyy-mm") -> 2025-07 | O20: =TEXT(tbl_Ledger[[#This Row],[Date]],"yyyy-mm") & TRIM(tbl_Ledger[[#This Row],[Currency]]) -> 2025-07NGN | P20: =_xlfn.XLOOKUP(tbl_Ledger[[#This Row],[Key]], tbl_FX[Key], tbl_FX[Rate_to_NGN]) -> 1 | Q20: =IF(tbl_Ledger[[#This Row],[Account_Type]]="Expense",-ABS(tbl_Ledger[[#This Row],[Amount]]*tbl_Ledger[[#This Row],[Rate_to_NGN]]),tbl_Ledger[[#This Row],[Amount]]*tbl_Ledger[[#This Row],[Rate_to_NGN]]) -> 27000 | R20: =_xlfn.XLOOKUP(tbl_Ledger[[#This Row],[Account_Code]], tbl_Accounts[Account_Code], tbl_Accounts[Type]) -> Revenue | S20: =_xlfn.XLOOKUP(tbl_Ledger[[#This Row],[Account_Code]], tbl_Accounts[Account_Code], tbl_Accounts[PL_Bucket]) -> Revenue | T20: =IF(AND(S20="Revenue",F20<>4900),ABS(Q20),-ABS(Q20)) -> 27000
A21: T100017 | B21: 45840 | C21: POS-Square | D21: Zumi Mart | E21: POS-Lekki | F21: 4000 | G21: Order Revenue | H21: POS-Lekki daily settlement 2025-07-02 | I21: NGN | J21: 50900 | L21: INV-20250702-POS | N21: =TEXT(tbl_Ledger[[#This Row],[Date]],"yyyy-mm") -> 2025-07 | O21: =TEXT(tbl_Ledger[[#This Row],[Date]],"yyyy-mm") & TRIM(tbl_Ledger[[#This Row],[Currency]]) -> 2025-07NGN | P21: =_xlfn.XLOOKUP(tbl_Ledger[[#This Row],[Key]], tbl_FX[Key], tbl_FX[Rate_to_NGN]) -> 1 | Q21: =IF(tbl_Ledger[[#This Row],[Account_Type]]="Expense",-ABS(tbl_Ledger[[#This Row],[Amount]]*tbl_Ledger[[#This Row],[Rate_to_NGN]]),tbl_Ledger[[#This Row],[Amount]]*tbl_Ledger[[#This Row],[Rate_to_NGN]]) -> 50900 | R21: =_xlfn.XLOOKUP(tbl_Ledger[[#This Row],[Account_Code]], tbl_Accounts[Account_Code], tbl_Accounts[Type]) -> Revenue | S21: =_xlfn.XLOOKUP(tbl_Ledger[[#This Row],[Account_Code]], tbl_Accounts[Account_Code], tbl_Accounts[PL_Bucket]) -> Revenue | T21: =IF(AND(S21="Revenue",F21<>4900),ABS(Q21),-ABS(Q21)) -> 50900
A22: T100018 | B22: 45840 | C22: POS-Square | D22: Zumi Mart | E22: POS-VI | F22: 4000 | G22: Order Revenue | H22: POS-VI daily settlement 2025-07-02 | I22: NGN | J22: 45500 | L22: INV-20250702-POS | N22: =TEXT(tbl_Ledger[[#This Row],[Date]],"yyyy-mm") -> 2025-07 | O22: =TEXT(tbl_Ledger[[#This Row],[Date]],"yyyy-mm") & TRIM(tbl_Ledger[[#This Row],[Currency]]) -> 2025-07NGN | P22: =_xlfn.XLOOKUP(tbl_Ledger[[#This Row],[Key]], tbl_FX[Key], tbl_FX[Rate_to_NGN]) -> 1 | Q22: =IF(tbl_Ledger[[#This Row],[Account_Type]]="Expense",-ABS(tbl_Ledger[[#This Row],[Amount]]*tbl_Ledger[[#This Row],[Rate_to_NGN]]),tbl_Ledger[[#This Row],[Amount]]*tbl_Ledger[[#This Row],[Rate_to_NGN]]) -> 45500 | R22: =_xlfn.XLOOKUP(tbl_Ledger[[#This Row],[Account_Code]], tbl_Accounts[Account_Code], tbl_Accounts[Type]) -> Revenue | S22: =_xlfn.XLOOKUP(tbl_Ledger[[#This Row],[Account_Code]], tbl_Accounts[Account_Code], tbl_Accounts[PL_Bucket]) -> Revenue | T22: =IF(AND(S22="Revenue",F22<>4900),ABS(Q22),-ABS(Q22)) -> 45500
A23: T100019 | B23: 45840 | C23: POS-Square | D23: Zumi Mart | E23: POS-Ikeja | F23: 4000 | G23: Order Revenue | H23: POS-Ikeja daily settlement 2025-07-02 | I23: NGN | J23: 48200 | L23: INV-20250702-POS | N23: =TEXT(tbl_Ledger[[#This Row],[Date]],"yyyy-mm") -> 2025-07 | O23: =TEXT(tbl_Ledger[[#This Row],[Date]],"yyyy-mm") & TRIM(tbl_Ledger[[#This Row],[Currency]]) -> 2025-07NGN | P23: =_xlfn.XLOOKUP(tbl_Ledger[[#This Row],[Key]], tbl_FX[Key], tbl_FX[Rate_to_NGN]) -> 1 | Q23: =IF(tbl_Ledger[[#This Row],[Account_Type]]="Expense",-ABS(tbl_Ledger[[#This Row],[Amount]]*tbl_Ledger[[#This Row],[Rate_to_NGN]]),tbl_Ledger[[#This Row],[Amount]]*tbl_Ledger[[#This Row],[Rate_to_NGN]]) -> 48200 | R23: =_xlfn.XLOOKUP(tbl_Ledger[[#This Row],[Account_Code]], tbl_Accounts[Account_Code], tbl_Accounts[Type]) -> Revenue | S23: =_xlfn.XLOOKUP(tbl_Ledger[[#This Row],[Account_Code]], tbl_Accounts[Account_Code], tbl_Accounts[PL_Bucket]) -> Revenue | T23: =IF(AND(S23="Revenue",F23<>4900),ABS(Q23),-ABS(Q23)) -> 48200
A24: T100020 | B24: 45840 | C24: POS-Square | D24: Zumi Mart | E24: POS-Abuja | F24: 4000 | G24: Order Revenue | H24: POS-Abuja daily settlement 2025-07-02 | I24: NGN | J24: 46900 | L24: INV-20250702-POS | N24: =TEXT(tbl_Ledger[[#This Row],[Date]],"yyyy-mm") -> 2025-07 | O24: =TEXT(tbl_Ledger[[#This Row],[Date]],"yyyy-mm") & TRIM(tbl_Ledger[[#This Row],[Currency]]) -> 2025-07NGN | P24: =_xlfn.XLOOKUP(tbl_Ledger[[#This Row],[Key]], tbl_FX[Key], tbl_FX[Rate_to_NGN]) -> 1 | Q24: =IF(tbl_Ledger[[#This Row],[Account_Type]]="Expense",-ABS(tbl_Ledger[[#This Row],[Amount]]*tbl_Ledger[[#This Row],[Rate_to_NGN]]),tbl_Ledger[[#This Row],[Amount]]*tbl_Ledger[[#This Row],[Rate_to_NGN]]) -> 46900 | R24: =_xlfn.XLOOKUP(tbl_Ledger[[#This Row],[Account_Code]], tbl_Accounts[Account_Code], tbl_Accounts[Type]) -> Revenue | S24: =_xlfn.XLOOKUP(tbl_Ledger[[#This Row],[Account_Code]], tbl_Accounts[Account_Code], tbl_Accounts[PL_Bucket]) -> Revenue | T24: =IF(AND(S24="Revenue",F24<>4900),ABS(Q24),-ABS(Q24)) -> 46900
A25: T100021 | B25: 45840 | C25: POS-Square | D25: Zumi Mart | E25: Online | F25: 4000 | G25: Order Revenue | H25: Online daily settlement 2025-07-02 | I25: NGN | J25: 49800 | L25: INV-20250702-ONL | N25: =TEXT(tbl_Ledger[[#This Row],[Date]],"yyyy-mm") -> 2025-07 | O25: =TEXT(tbl_Ledger[[#This Row],[Date]],"yyyy-mm") & TRIM(tbl_Ledger[[#This Row],[Currency]]) -> 2025-07NGN | P25: =_xlfn.XLOOKUP(tbl_Ledger[[#This Row],[Key]], tbl_FX[Key], tbl_FX[Rate_to_NGN]) -> 1 | Q25: =IF(tbl_Ledger[[#This Row],[Account_Type]]="Expense",-ABS(tbl_Ledger[[#This Row],[Amount]]*tbl_Ledger[[#This Row],[Rate_to_NGN]]),tbl_Ledger[[#This Row],[Amount]]*tbl_Ledger[[#This Row],[Rate_to_NGN]]) -> 49800 | R25: =_xlfn.XLOOKUP(tbl_Ledger[[#This Row],[Account_Code]], tbl_Accounts[Account_Code], tbl_Accounts[Type]) -> Revenue | S25: =_xlfn.XLOOKUP(tbl_Ledger[[#This Row],[Account_Code]], tbl_Accounts[Account_Code], tbl_Accounts[PL_Bucket]) -> Revenue | T25: =IF(AND(S25="Revenue",F25<>4900),ABS(Q25),-ABS(Q25)) -> 49800
A26: T100022 | B26: 45840 | C26: NetSuite | D26: Zumi Logistics | E26: Contract-Dangote | F26: 4020 | G26: Logistics Contract Revenue | H26: Contract-Dangote daily settlement 2025-07-02 | I26: USD | J26: 28.56 | K26: Dangote | L26: INV-20250702-CON | N26: =TEXT(tbl_Ledger[[#This Row],[Date]],"yyyy-mm") -> 2025-07 | O26: =TEXT(tbl_Ledger[[#This Row],[Date]],"yyyy-mm") & TRIM(tbl_Ledger[[#This Row],[Currency]]) -> 2025-07USD | P26: =_xlfn.XLOOKUP(tbl_Ledger[[#This Row],[Key]], tbl_FX[Key], tbl_FX[Rate_to_NGN]) -> 1530 | Q26: =IF(tbl_Ledger[[#This Row],[Account_Type]]="Expense",-ABS(tbl_Ledger[[#This Row],[Amount]]*tbl_Ledger[[#This Row],[Rate_to_NGN]]),tbl_Ledger[[#This Row],[Amount]]*tbl_Ledger[[#This Row],[Rate_to_NGN]]) -> 43696.8 | R26: =_xlfn.XLOOKUP(tbl_Ledger[[#This Row],[Account_Code]], tbl_Accounts[Account_Code], tbl_Accounts[Type]) -> Revenue | S26: =_xlfn.XLOOKUP(tbl_Ledger[[#This Row],[Account_Code]], tbl_Accounts[Account_Code], tbl_Accounts[PL_Bucket]) -> Revenue | T26: =IF(AND(S26="Revenue",F26<>4900),ABS(Q26),-ABS(Q26)) -> 43696.8
A27: T100023 | B27: 45840 | C27: NetSuite | D27: Zumi Logistics | E27: Contract-MTN | F27: 4020 | G27: Logistics Contract Revenue | H27: Contract-MTN daily settlement 2025-07-02 | I27: NGN | J27: 49900 | K27: MTN | L27: INV-20250702-CON | N27: =TEXT(tbl_Ledger[[#This Row],[Date]],"yyyy-mm") -> 2025-07 | O27: =TEXT(tbl_Ledger[[#This Row],[Date]],"yyyy-mm") & TRIM(tbl_Ledger[[#This Row],[Currency]]) -> 2025-07NGN | P27: =_xlfn.XLOOKUP(tbl_Ledger[[#This Row],[Key]], tbl_FX[Key], tbl_FX[Rate_to_NGN]) -> 1 | Q27: =IF(tbl_Ledger[[#This Row],[Account_Type]]="Expense",-ABS(tbl_Ledger[[#This Row],[Amount]]*tbl_Ledger[[#This Row],[Rate_to_NGN]]),tbl_Ledger[[#This Row],[Amount]]*tbl_Ledger[[#This Row],[Rate_to_NGN]]) -> 49900 | R27: =_xlfn.XLOOKUP(tbl_Ledger[[#This Row],[Account_Code]], tbl_Accounts[Account_Code], tbl_Accounts[Type]) -> Revenue | S27: =_xlfn.XLOOKUP(tbl_Ledger[[#This Row],[Account_Code]], tbl_Accounts[Account_Code], tbl_Accounts[PL_Bucket]) -> Revenue | T27: =IF(AND(S27="Revenue",F27<>4900),ABS(Q27),-ABS(Q27)) -> 49900
A28: T100024 | B28: 45840 | C28: NetSuite | D28: Zumi Logistics | E28: Contract-Flutterwave | F28: 4020 | G28: Logistics Contract Revenue | H28: Contract-Flutterwave daily settlement 2025-07-02 | I28: NGN | J28: 48500 | K28: Flutterwave | L28: INV-20250702-CON | N28: =TEXT(tbl_Ledger[[#This Row],[Date]],"yyyy-mm") -> 2025-07 | O28: =TEXT(tbl_Ledger[[#This Row],[Date]],"yyyy-mm") & TRIM(tbl_Ledger[[#This Row],[Currency]]) -> 2025-07NGN | P28: =_xlfn.XLOOKUP(tbl_Ledger[[#This Row],[Key]], tbl_FX[Key], tbl_FX[Rate_to_NGN]) -> 1 | Q28: =IF(tbl_Ledger[[#This Row],[Account_Type]]="Expense",-ABS(tbl_Ledger[[#This Row],[Amount]]*tbl_Ledger[[#This Row],[Rate_to_NGN]]),tbl_Ledger[[#This Row],[Amount]]*tbl_Ledger[[#This Row],[Rate_to_NGN]]) -> 48500 | R28: =_xlfn.XLOOKUP(tbl_Ledger[[#This Row],[Account_Code]], tbl_Accounts[Account_Code], tbl_Accounts[Type]) -> Revenue | S28: =_xlfn.XLOOKUP(tbl_Ledger[[#This Row],[Account_Code]], tbl_Accounts[Account_Code], tbl_Accounts[PL_Bucket]) -> Revenue | T28: =IF(AND(S28="Revenue",F28<>4900),ABS(Q28),-ABS(Q28)) -> 48500
A29: T100025 | B29: 45840 | C29: NetSuite | D29: Zumi Logistics | E29: Spot-Market | F29: 4020 | G29: Logistics Contract Revenue | H29: Spot-Market daily settlement 2025-07-02 | I29: NGN | J29: 48000 | L29: INV-20250702-SPO | N29: =TEXT(tbl_Ledger[[#This Row],[Date]],"yyyy-mm") -> 2025-07 | O29: =TEXT(tbl_Ledger[[#This Row],[Date]],"yyyy-mm") & TRIM(tbl_Ledger[[#This Row],[Currency]]) -> 2025-07NGN | P29: =_xlfn.XLOOKUP(tbl_Ledger[[#This Row],[Key]], tbl_FX[Key], tbl_FX[Rate_to_NGN]) -> 1 | Q29: =IF(tbl_Ledger[[#This Row],[Account_Type]]="Expense",-ABS(tbl_Ledger[[#This Row],[Amount]]*tbl_Ledger[[#This Row],[Rate_to_NGN]]),tbl_Ledger[[#This Row],[Amount]]*tbl_Ledger[[#This Row],[Rate_to_NGN]]) -> 48000 | R29: =_xlfn.XLOOKUP(tbl_Ledger[[#This Row],[Account_Code]], tbl_Accounts[Account_Code], tbl_Accounts[Type]) -> Revenue | S29: =_xlfn.XLOOKUP(tbl_Ledger[[#This Row],[Account_Code]], tbl_Accounts[Account_Code], tbl_Accounts[PL_Bucket]) -> Revenue | T29: =IF(AND(S29="Revenue",F29<>4900),ABS(Q29),-ABS(Q29)) -> 48000
A30: T101239 | B30: 45840 | C30: QuickBooks | D30: Zumi Eats | F30: 5040 | G30: Rider Payouts | H30: Rider Payroll invoice 2025-07 | I30: NGN | J30: -562000 | K30: Rider Payroll | L30: BILL-47775 | N30: =TEXT(tbl_Ledger[[#This Row],[Date]],"yyyy-mm") -> 2025-07 | O30: =TEXT(tbl_Ledger[[#This Row],[Date]],"yyyy-mm") & TRIM(tbl_Ledger[[#This Row],[Currency]]) -> 2025-07NGN | P30: =_xlfn.XLOOKUP(tbl_Ledger[[#This Row],[Key]], tbl_FX[Key], tbl_FX[Rate_to_NGN]) -> 1 | Q30: =IF(tbl_Ledger[[#This Row],[Account_Type]]="Expense",-ABS(tbl_Ledger[[#This Row],[Amount]]*tbl_Ledger[[#This Row],[Rate_to_NGN]]),tbl_Ledger[[#This Row],[Amount]]*tbl_Ledger[[#This Row],[Rate_to_NGN]]) -> -562000 | R30: =_xlfn.XLOOKUP(tbl_Ledger[[#This Row],[Account_Code]], tbl_Accounts[Account_Code], tbl_Accounts[Type]) -> COGS | S30: =_xlfn.XLOOKUP(tbl_Ledger[[#This Row],[Account_Code]], tbl_Accounts[Account_Code], tbl_Accounts[PL_Bucket]) -> COGS | T30: =IF(AND(S30="Revenue",F30<>4900),ABS(Q30),-ABS(Q30)) -> -562000
A31: T101243 | B31: 45840 | C31: QuickBooks | D31: Zumi Eats | F31: 5050 | G31: Aggregator Commission | H31: Bolt Food invoice 2025-07 | I31: NGN | J31: -255000 | K31: Bolt Food | L31: BILL-82046 | N31: =TEXT(tbl_Ledger[[#This Row],[Date]],"yyyy-mm") -> 2025-07 | O31: =TEXT(tbl_Ledger[[#This Row],[Date]],"yyyy-mm") & TRIM(tbl_Ledger[[#This Row],[Currency]]) -> 2025-07NGN | P31: =_xlfn.XLOOKUP(tbl_Ledger[[#This Row],[Key]], tbl_FX[Key], tbl_FX[Rate_to_NGN]) -> 1 | Q31: =IF(tbl_Ledger[[#This Row],[Account_Type]]="Expense",-ABS(tbl_Ledger[[#This Row],[Amount]]*tbl_Ledger[[#This Row],[Rate_to_NGN]]),tbl_Ledger[[#This Row],[Amount]]*tbl_Ledger[[#This Row],[Rate_to_NGN]]) -> -255000 | R31: =_xlfn.XLOOKUP(tbl_Ledger[[#This Row],[Account_Code]], tbl_Accounts[Account_Code], tbl_Accounts[Type]) -> COGS | S31: =_xlfn.XLOOKUP(tbl_Ledger[[#This Row],[Account_Code]], tbl_Accounts[Account_Code], tbl_Accounts[PL_Bucket]) -> COGS | T31: =IF(AND(S31="Revenue",F31<>4900),ABS(Q31),-ABS(Q31)) -> -255000
A32: T101254 | B32: 45840 | C32: QuickBooks | D32: Zumi Mart | F32: 5010 | G32: Inventory Purchases | H32: Dangote Sugar invoice 2025-07 | I32: NGN | J32: -862000 | K32: Dangote Sugar | L32: BILL-69162 | N32: =TEXT(tbl_Ledger[[#This Row],[Date]],"yyyy-mm") -> 2025-07 | O32: =TEXT(tbl_Ledger[[#This Row],[Date]],"yyyy-mm") & TRIM(tbl_Ledger[[#This Row],[Currency]]) -> 2025-07NGN | P32: =_xlfn.XLOOKUP(tbl_Ledger[[#This Row],[Key]], tbl_FX[Key], tbl_FX[Rate_to_NGN]) -> 1 | Q32: =IF(tbl_Ledger[[#This Row],[Account_Type]]="Expense",-ABS(tbl_Ledger[[#This Row],[Amount]]*tbl_Ledger[[#This Row],[Rate_to_NGN]]),tbl_Ledger[[#This Row],[Amount]]*tbl_Ledger[[#This Row],[Rate_to_NGN]]) -> -862000 | R32: =_xlfn.XLOOKUP(tbl_Ledger[[#This Row],[Account_Code]], tbl_Accounts[Account_Code], tbl_Accounts[Type]) -> COGS | S32: =_xlfn.XLOOKUP(tbl_Ledger[[#This Row],[Account_Code]], tbl_Accounts[Account_Code], tbl_Accounts[PL_Bucket]) -> COGS | T32: =IF(AND(S32="Revenue",F32<>4900),ABS(Q32),-ABS(Q32)) -> -862000
A33: T101394 | B33: 45840 | C33: QuickBooks | D33: Zumi Eats | F33: 6040 | G33: Software & Tools | H33: SaaS subscriptions 2025-07 | I33: USD | J33: -820 | K33: Various SaaS | L33: SAAS-2025-07 | N33: =TEXT(tbl_Ledger[[#This Row],[Date]],"yyyy-mm") -> 2025-07 | O33: =TEXT(tbl_Ledger[[#This Row],[Date]],"yyyy-mm") & TRIM(tbl_Ledger[[#This Row],[Currency]]) -> 2025-07USD | P33: =_xlfn.XLOOKUP(tbl_Ledger[[#This Row],[Key]], tbl_FX[Key], tbl_FX[Rate_to_NGN]) -> 1530 | Q33: =IF(tbl_Ledger[[#This Row],[Account_Type]]="Expense",-ABS(tbl_Ledger[[#This Row],[Amount]]*tbl_Ledger[[#This Row],[Rate_to_NGN]]),tbl_Ledger[[#This Row],[Amount]]*tbl_Ledger[[#This Row],[Rate_to_NGN]]) -> -1254600 | R33: =_xlfn.XLOOKUP(tbl_Ledger[[#This Row],[Account_Code]], tbl_Accounts[Account_Code], tbl_Accounts[Type]) -> Opex | S33: =_xlfn.XLOOKUP(tbl_Ledger[[#This Row],[Account_Code]], tbl_Accounts[Account_Code], tbl_Accounts[PL_Bucket]) -> Opex | T33: =IF(AND(S33="Revenue",F33<>4900),ABS(Q33),-ABS(Q33)) -> -1254600
A34: T100026 | B34: 45841 | C34: POS-Square | D34: Zumi Eats | E34: Mobile App | F34: 4000 | G34: Order Revenue | H34: Mobile App daily settlement 2025-07-03 | I34: NGN | J34: 30100 | L34: INV-20250703-MOB | N34: =TEXT(tbl_Ledger[[#This Row],[Date]],"yyyy-mm") -> 2025-07 | O34: =TEXT(tbl_Ledger[[#This Row],[Date]],"yyyy-mm") & TRIM(tbl_Ledger[[#This Row],[Currency]]) -> 2025-07NGN | P34: =_xlfn.XLOOKUP(tbl_Ledger[[#This Row],[Key]], tbl_FX[Key], tbl_FX[Rate_to_NGN]) -> 1 | Q34: =IF(tbl_Ledger[[#This Row],[Account_Type]]="Expense",-ABS(tbl_Ledger[[#This Row],[Amount]]*tbl_Ledger[[#This Row],[Rate_to_NGN]]),tbl_Ledger[[#This Row],[Amount]]*tbl_Ledger[[#This Row],[Rate_to_NGN]]) -> 30100 | R34: =_xlfn.XLOOKUP(tbl_Ledger[[#This Row],[Account_Code]], tbl_Accounts[Account_Code], tbl_Accounts[Type]) -> Revenue | S34: =_xlfn.XLOOKUP(tbl_Ledger[[#This Row],[Account_Code]], tbl_Accounts[Account_Code], tbl_Accounts[PL_Bucket]) -> Revenue | T34: =IF(AND(S34="Revenue",F34<>4900),ABS(Q34),-ABS(Q34)) -> 30100
A35: T100027 | B35: 45841 | C35: POS-Square | D35: Zumi Eats | E35: Website | F35: 4000 | G35: Order Revenue | H35: Website daily settlement 2025-07-03 | I35: NGN | J35: 30400 | L35: INV-20250703-WEB | N35: =TEXT(tbl_Ledger[[#This Row],[Date]],"yyyy-mm") -> 2025-07 | O35: =TEXT(tbl_Ledger[[#This Row],[Date]],"yyyy-mm") & TRIM(tbl_Ledger[[#This Row],[Currency]]) -> 2025-07NGN | P35: =_xlfn.XLOOKUP(tbl_Ledger[[#This Row],[Key]], tbl_FX[Key], tbl_FX[Rate_to_NGN]) -> 1 | Q35: =IF(tbl_Ledger[[#This Row],[Account_Type]]="Expense",-ABS(tbl_Ledger[[#This Row],[Amount]]*tbl_Ledger[[#This Row],[Rate_to_NGN]]),tbl_Ledger[[#This Row],[Amount]]*tbl_Ledger[[#This Row],[Rate_to_NGN]]) -> 30400 | R35: =_xlfn.XLOOKUP(tbl_Ledger[[#This Row],[Account_Code]], tbl_Accounts[Account_Code], tbl_Accounts[Type]) -> Revenue | S35: =_xlfn.XLOOKUP(tbl_Ledger[[#This Row],[Account_Code]], tbl_Accounts[Account_Code], tbl_Accounts[PL_Bucket]) -> Revenue | T35: =IF(AND(S35="Revenue",F35<>4900),ABS(Q35),-ABS(Q35)) -> 30400
A36: T100028 | B36: 45841 | C36: POS-Square | D36: Zumi Eats | E36: Aggregator-Glovo | F36: 4000 | G36: Order Revenue | H36: Aggregator-Glovo daily settlement 2025-07-03 | I36: NGN | J36: 30700 | L36: INV-20250703-AGG | N36: =TEXT(tbl_Ledger[[#This Row],[Date]],"yyyy-mm") -> 2025-07 | O36: =TEXT(tbl_Ledger[[#This Row],[Date]],"yyyy-mm") & TRIM(tbl_Ledger[[#This Row],[Currency]]) -> 2025-07NGN | P36: =_xlfn.XLOOKUP(tbl_Ledger[[#This Row],[Key]], tbl_FX[Key], tbl_FX[Rate_to_NGN]) -> 1 | Q36: =IF(tbl_Ledger[[#This Row],[Account_Type]]="Expense",-ABS(tbl_Ledger[[#This Row],[Amount]]*tbl_Ledger[[#This Row],[Rate_to_NGN]]),tbl_Ledger[[#This Row],[Amount]]*tbl_Ledger[[#This Row],[Rate_to_NGN]]) -> 30700 | R36: =_xlfn.XLOOKUP(tbl_Ledger[[#This Row],[Account_Code]], tbl_Accounts[Account_Code], tbl_Accounts[Type]) -> Revenue | S36: =_xlfn.XLOOKUP(tbl_Ledger[[#This Row],[Account_Code]], tbl_Accounts[Account_Code], tbl_Accounts[PL_Bucket]) -> Revenue | T36: =IF(AND(S36="Revenue",F36<>4900),ABS(Q36),-ABS(Q36)) -> 30700
A37: T100029 | B37: 45841 | C37: POS-Square | D37: Zumi Eats | E37: Aggregator-Bolt | F37: 4000 | G37: Order Revenue | H37: Aggregator-Bolt daily settlement 2025-07-03 | I37: NGN | J37: 28100 | L37: INV-20250703-AGG | N37: =TEXT(tbl_Ledger[[#This Row],[Date]],"yyyy-mm") -> 2025-07 | O37: =TEXT(tbl_Ledger[[#This Row],[Date]],"yyyy-mm") & TRIM(tbl_Ledger[[#This Row],[Currency]]) -> 2025-07NGN | P37: =_xlfn.XLOOKUP(tbl_Ledger[[#This Row],[Key]], tbl_FX[Key], tbl_FX[Rate_to_NGN]) -> 1 | Q37: =IF(tbl_Ledger[[#This Row],[Account_Type]]="Expense",-ABS(tbl_Ledger[[#This Row],[Amount]]*tbl_Ledger[[#This Row],[Rate_to_NGN]]),tbl_Ledger[[#This Row],[Amount]]*tbl_Ledger[[#This Row],[Rate_to_NGN]]) -> 28100 | R37: =_xlfn.XLOOKUP(tbl_Ledger[[#This Row],[Account_Code]], tbl_Accounts[Account_Code], tbl_Accounts[Type]) -> Revenue | S37: =_xlfn.XLOOKUP(tbl_Ledger[[#This Row],[Account_Code]], tbl_Accounts[Account_Code], tbl_Accounts[PL_Bucket]) -> Revenue | T37: =IF(AND(S37="Revenue",F37<>4900),ABS(Q37),-ABS(Q37)) -> 28100
A38: T100030 | B38: 45841 | C38: POS-Square | D38: Zumi Mart | E38: POS-Lekki | F38: 4000 | G38: Order Revenue | H38: POS-Lekki daily settlement 2025-07-03 | I38: NGN | J38: 48100 | L38: INV-20250703-POS | N38: =TEXT(tbl_Ledger[[#This Row],[Date]],"yyyy-mm") -> 2025-07 | O38: =TEXT(tbl_Ledger[[#This Row],[Date]],"yyyy-mm") & TRIM(tbl_Ledger[[#This Row],[Currency]]) -> 2025-07NGN | P38: =_xlfn.XLOOKUP(tbl_Ledger[[#This Row],[Key]], tbl_FX[Key], tbl_FX[Rate_to_NGN]) -> 1 | Q38: =IF(tbl_Ledger[[#This Row],[Account_Type]]="Expense",-ABS(tbl_Ledger[[#This Row],[Amount]]*tbl_Ledger[[#This Row],[Rate_to_NGN]]),tbl_Ledger[[#This Row],[Amount]]*tbl_Ledger[[#This Row],[Rate_to_NGN]]) -> 48100 | R38: =_xlfn.XLOOKUP(tbl_Ledger[[#This Row],[Account_Code]], tbl_Accounts[Account_Code], tbl_Accounts[Type]) -> Revenue | S38: =_xlfn.XLOOKUP(tbl_Ledger[[#This Row],[Account_Code]], tbl_Accounts[Account_Code], tbl_Accounts[PL_Bucket]) -> Revenue | T38: =IF(AND(S38="Revenue",F38<>4900),ABS(Q38),-ABS(Q38)) -> 48100
A39: T100031 | B39: 45841 | C39: POS-Square | D39: Zumi Mart | E39: POS-VI | F39: 4000 | G39: Order Revenue | H39: POS-VI daily settlement 2025-07-03 | I39: NGN | J39: 47100 | L39: INV-20250703-POS | N39: =TEXT(tbl_Ledger[[#This Row],[Date]],"yyyy-mm") -> 2025-07 | O39: =TEXT(tbl_Ledger[[#This Row],[Date]],"yyyy-mm") & TRIM(tbl_Ledger[[#This Row],[Currency]]) -> 2025-07NGN | P39: =_xlfn.XLOOKUP(tbl_Ledger[[#This Row],[Key]], tbl_FX[Key], tbl_FX[Rate_to_NGN]) -> 1 | Q39: =IF(tbl_Ledger[[#This Row],[Account_Type]]="Expense",-ABS(tbl_Ledger[[#This Row],[Amount]]*tbl_Ledger[[#This Row],[Rate_to_NGN]]),tbl_Ledger[[#This Row],[Amount]]*tbl_Ledger[[#This Row],[Rate_to_NGN]]) -> 47100 | R39: =_xlfn.XLOOKUP(tbl_Ledger[[#This Row],[Account_Code]], tbl_Accounts[Account_Code], tbl_Accounts[Type]) -> Revenue | S39: =_xlfn.XLOOKUP(tbl_Ledger[[#This Row],[Account_Code]], tbl_Accounts[Account_Code], tbl_Accounts[PL_Bucket]) -> Revenue | T39: =IF(AND(S39="Revenue",F39<>4900),ABS(Q39),-ABS(Q39)) -> 47100
A40: T100032 | B40: 45841 | C40: POS-Square | D40: Zumi Mart | E40: POS-Ikeja | F40: 4000 | G40: Order Revenue | H40: POS-Ikeja daily settlement 2025-07-03 | I40: NGN | J40: 50400 | L40: INV-20250703-POS | N40: =TEXT(tbl_Ledger[[#This Row],[Date]],"yyyy-mm") -> 2025-07 | O40: =TEXT(tbl_Ledger[[#This Row],[Date]],"yyyy-mm") & TRIM(tbl_Ledger[[#This Row],[Currency]]) -> 2025-07NGN | P40: =_xlfn.XLOOKUP(tbl_Ledger[[#This Row],[Key]], tbl_FX[Key], tbl_FX[Rate_to_NGN]) -> 1 | Q40: =IF(tbl_Ledger[[#This Row],[Account_Type]]="Expense",-ABS(tbl_Ledger[[#This Row],[Amount]]*tbl_Ledger[[#This Row],[Rate_to_NGN]]),tbl_Ledger[[#This Row],[Amount]]*tbl_Ledger[[#This Row],[Rate_to_NGN]]) -> 50400 | R40: =_xlfn.XLOOKUP(tbl_Ledger[[#This Row],[Account_Code]], tbl_Accounts[Account_Code], tbl_Accounts[Type]) -> Revenue | S40: =_xlfn.XLOOKUP(tbl_Ledger[[#This Row],[Account_Code]], tbl_Accounts[Account_Code], tbl_Accounts[PL_Bucket]) -> Revenue | T40: =IF(AND(S40="Revenue",F40<>4900),ABS(Q40),-ABS(Q40)) -> 50400
...

Sheet Issues_Log
A1: Issue_# | B1: Txn_ID | C1: Date | D1: Brand | E1: Amount_NGN | F1: Issue_Type | G1: Action_Taken
A2: 1 | B2: T101433 | C2: =_xlfn.XLOOKUP(B2,tbl_Ledger[Txn_ID],tbl_Ledger[Date]) -> 45881 | D2: =_xlfn.XLOOKUP(B2,tbl_Ledger[Txn_ID],tbl_Ledger[Brand]) -> Zumi Mart | E2: =_xlfn.XLOOKUP(B2,tbl_Ledger[Txn_ID],tbl_Ledger[Adjusted_Amount_NGN]) -> -1840000 | F2: Duplicate Vendor Invoice | G2: Excluded - Distell Wholesale paid twice same week, same amount
A3: 2 | B3: T101402 | C3: =_xlfn.XLOOKUP(B3,tbl_Ledger[Txn_ID],tbl_Ledger[Date]) -> 45894 | D3: =_xlfn.XLOOKUP(B3,tbl_Ledger[Txn_ID],tbl_Ledger[Brand]) -> Zumi Mart | E3: =_xlfn.XLOOKUP(B3,tbl_Ledger[Txn_ID],tbl_Ledger[Adjusted_Amount_NGN]) -> -680000 | F3: Duplicate Payroll Entry | G3: Excluded - same employee same month, already captured in T101401
A4: 3 | B4: T101419 | C4: =_xlfn.XLOOKUP(B4,tbl_Ledger[Txn_ID],tbl_Ledger[Date]) -> 45925 | D4: =_xlfn.XLOOKUP(B4,tbl_Ledger[Txn_ID],tbl_Ledger[Brand]) -> Zumi Eats | E4: =_xlfn.XLOOKUP(B4,tbl_Ledger[Txn_ID],tbl_Ledger[Adjusted_Amount_NGN]) -> -540000 | F4: Misclassified Brand | G4: Reclassified from Zumi Eats to Zumi Logistics - rider supervisor belongs to Logistics
A5: 4 | B5: T101435 | C5: 45922 | D5: =_xlfn.XLOOKUP(B5,tbl_Ledger[Txn_ID],tbl_Ledger[Brand]) -> Zumi Eats | E5: =_xlfn.XLOOKUP(B5,tbl_Ledger[Txn_ID],tbl_Ledger[Adjusted_Amount_NGN]) -> -180000 | F5: Uncategorized Cash Withdrawal | G5: Parked separately - no GL code, excluded from OpEx, flagged for CEO review
A6: 5 | B6: T101434 | C6: Unknown | D6: =_xlfn.XLOOKUP(B6,tbl_Ledger[Txn_ID],tbl_Ledger[Brand]) -> Zumi Logistics | E6: =_xlfn.XLOOKUP(B6,tbl_Ledger[Txn_ID],tbl_Ledger[Adjusted_Amount_NGN]) -> -240000 | F6: Missing Transaction Date | G6: Excluded from P&L - date stored as Excel serial number 45839, cannot assign to month
A7: 6 | B7: Multiple - Account 4900 | C7: 2025-07 to 2025-09 | D7: All Brands | E7: =SUMIFS(tbl_Cleaned[Clean_Amount],tbl_Cleaned[Account_Name],"Refunds & Chargebacks") -> -2962453 | F7: Refunds Booked as Positive | G7: Fixed in Clean_Amount formula - all Account 4900 rows forced negative via IF/ABS formula
A9: Total NGN Impact of Issues | E9: =SUM(E2:E7) -> -6442453

Sheet tbl_Cleaned
A1: Txn_ID | B1: Date | C1: Source_System | D1: Brand | E1: Channel | F1: Account_Code | G1: Account_Name | H1: Description | I1: Currency | J1: Amount | K1: Vendor_or_Customer | L1: Reference | M1: Notes | N1: Month | O1: Key | P1: Rate_to_NGN | Q1: Adjusted_Amount_NGN | R1: Account_Type | S1: PL_Bucket | T1: Clean_Amount
A2: T100001 | B2: 45839 | C2: POS-Square | D2: Zumi Eats | E2: Mobile App | F2: 4000 | G2: Order Revenue | H2: Mobile App daily settlement 2025-07-01 | I2: NGN | J2: 27600 | L2: INV-20250701-MOB | N2: 2025-07 | O2: 2025-07NGN | P2: 1 | Q2: 27600 | R2: Revenue | S2: Revenue | T2: =IF(AND(S2="Revenue",G2<>"Refunds & Chargebacks"),ABS(Q2),-ABS(Q2)) -> 27600
A3: T100002 | B3: 45839 | C3: POS-Square | D3: Zumi Eats | E3: Website | F3: 4000 | G3: Order Revenue | H3: Website daily settlement 2025-07-01 | I3: NGN | J3: 29800 | L3: INV-20250701-WEB | N3: 2025-07 | O3: 2025-07NGN | P3: 1 | Q3: 29800 | R3: Revenue | S3: Revenue | T3: =IF(AND(S3="Revenue",G3<>"Refunds & Chargebacks"),ABS(Q3),-ABS(Q3)) -> 29800
A4: T100003 | B4: 45839 | C4: POS-Square | D4: Zumi Eats | E4: Aggregator-Glovo | F4: 4000 | G4: Order Revenue | H4: Aggregator-Glovo daily settlement 2025-07-01 | I4: NGN | J4: 29500 | L4: INV-20250701-AGG | N4: 2025-07 | O4: 2025-07NGN | P4: 1 | Q4: 29500 | R4: Revenue | S4: Revenue | T4: =IF(AND(S4="Revenue",G4<>"Refunds & Chargebacks"),ABS(Q4),-ABS(Q4)) -> 29500
A5: T100004 | B5: 45839 | C5: POS-Square | D5: Zumi Eats | E5: Walk-in | F5: 4000 | G5: Order Revenue | H5: Walk-in daily settlement 2025-07-01 | I5: NGN | J5: 31400 | L5: INV-20250701-WAL | N5: 2025-07 | O5: 2025-07NGN | P5: 1 | Q5: 31400 | R5: Revenue | S5: Revenue | T5: =IF(AND(S5="Revenue",G5<>"Refunds & Chargebacks"),ABS(Q5),-ABS(Q5)) -> 31400
A6: T100005 | B6: 45839 | C6: POS-Square | D6: Zumi Mart | E6: POS-Lekki | F6: 4000 | G6: Order Revenue | H6: POS-Lekki daily settlement 2025-07-01 | I6: NGN | J6: 48600 | L6: INV-20250701-POS | N6: 2025-07 | O6: 2025-07NGN | P6: 1 | Q6: 48600 | R6: Revenue | S6: Revenue | T6: =IF(AND(S6="Revenue",G6<>"Refunds & Chargebacks"),ABS(Q6),-ABS(Q6)) -> 48600
A7: T100006 | B7: 45839 | C7: POS-Square | D7: Zumi Mart | E7: POS-VI | F7: 4000 | G7: Order Revenue | H7: POS-VI daily settlement 2025-07-01 | I7: NGN | J7: 45700 | L7: INV-20250701-POS | N7: 2025-07 | O7: 2025-07NGN | P7: 1 | Q7: 45700 | R7: Revenue | S7: Revenue | T7: =IF(AND(S7="Revenue",G7<>"Refunds & Chargebacks"),ABS(Q7),-ABS(Q7)) -> 45700
A8: T100007 | B8: 45839 | C8: POS-Square | D8: Zumi Mart | E8: POS-Ikeja | F8: 4000 | G8: Order Revenue | H8: POS-Ikeja daily settlement 2025-07-01 | I8: NGN | J8: 46300 | L8: INV-20250701-POS | N8: 2025-07 | O8: 2025-07NGN | P8: 1 | Q8: 46300 | R8: Revenue | S8: Revenue | T8: =IF(AND(S8="Revenue",G8<>"Refunds & Chargebacks"),ABS(Q8),-ABS(Q8)) -> 46300
A9: T100008 | B9: 45839 | C9: POS-Square | D9: Zumi Mart | E9: Online | F9: 4000 | G9: Order Revenue | H9: Online daily settlement 2025-07-01 | I9: NGN | J9: 49000 | L9: INV-20250701-ONL | N9: 2025-07 | O9: 2025-07NGN | P9: 1 | Q9: 49000 | R9: Revenue | S9: Revenue | T9: =IF(AND(S9="Revenue",G9<>"Refunds & Chargebacks"),ABS(Q9),-ABS(Q9)) -> 49000
A10: T100009 | B10: 45839 | C10: NetSuite | D10: Zumi Logistics | E10: Contract-Dangote | F10: 4020 | G10: Logistics Contract Revenue | H10: Contract-Dangote daily settlement 2025-07-01 | I10: NGN | J10: 41900 | K10: Dangote | L10: INV-20250701-CON | N10: 2025-07 | O10: 2025-07NGN | P10: 1 | Q10: 41900 | R10: Revenue | S10: Revenue | T10: =IF(AND(S10="Revenue",G10<>"Refunds & Chargebacks"),ABS(Q10),-ABS(Q10)) -> 41900
A11: T100010 | B11: 45839 | C11: NetSuite | D11: Zumi Logistics | E11: Contract-MTN | F11: 4020 | G11: Logistics Contract Revenue | H11: Contract-MTN daily settlement 2025-07-01 | I11: USD | J11: 28.04 | K11: MTN | L11: INV-20250701-CON | N11: 2025-07 | O11: 2025-07USD | P11: 1530 | Q11: 42901.2 | R11: Revenue | S11: Revenue | T11: =IF(AND(S11="Revenue",G11<>"Refunds & Chargebacks"),ABS(Q11),-ABS(Q11)) -> 42901.2
A12: T100011 | B12: 45839 | C12: NetSuite | D12: Zumi Logistics | E12: Contract-Flutterwave | F12: 4020 | G12: Logistics Contract Revenue | H12: Contract-Flutterwave daily settlement 2025-07-01 | I12: USD | J12: 28.95 | K12: Flutterwave | L12: INV-20250701-CON | N12: 2025-07 | O12: 2025-07USD | P12: 1530 | Q12: 44293.5 | R12: Revenue | S12: Revenue | T12: =IF(AND(S12="Revenue",G12<>"Refunds & Chargebacks"),ABS(Q12),-ABS(Q12)) -> 44293.5
A13: T100012 | B13: 45839 | C13: NetSuite | D13: Zumi Logistics | E13: Spot-Market | F13: 4020 | G13: Logistics Contract Revenue | H13: Spot-Market daily settlement 2025-07-01 | I13: NGN | J13: 47700 | L13: INV-20250701-SPO | N13: 2025-07 | O13: 2025-07NGN | P13: 1 | Q13: 47700 | R13: Revenue | S13: Revenue | T13: =IF(AND(S13="Revenue",G13<>"Refunds & Chargebacks"),ABS(Q13),-ABS(Q13)) -> 47700
A14: T101249 | B14: 45839 | C14: QuickBooks | D14: Zumi Mart | F14: 5010 | G14: Inventory Purchases | H14: Distell Wholesale invoice 2025-07 | I14: NGN | J14: -1691000 | K14: Distell Wholesale | L14: BILL-13747 | N14: 2025-07 | O14: 2025-07NGN | P14: 1 | Q14: -1691000 | R14: COGS | S14: COGS | T14: =IF(AND(S14="Revenue",G14<>"Refunds & Chargebacks"),ABS(Q14),-ABS(Q14)) -> -1691000
A15: T101265 | B15: 45839 | C15: QuickBooks | D15: Zumi Logistics | F15: 5030 | G15: Fuel & Vehicle | H15: NNPC Retail invoice 2025-07 | I15: NGN | J15: -522000 | K15: NNPC Retail | L15: BILL-18601 | N15: 2025-07 | O15: 2025-07NGN | P15: 1 | Q15: -522000 | R15: COGS | S15: COGS | T15: =IF(AND(S15="Revenue",G15<>"Refunds & Chargebacks"),ABS(Q15),-ABS(Q15)) -> -522000
A16: T100013 | B16: 45840 | C16: POS-Square | D16: Zumi Eats | E16: Mobile App | F16: 4000 | G16: Order Revenue | H16: Mobile App daily settlement 2025-07-02 | I16: NGN | J16: 31500 | L16: INV-20250702-MOB | N16: 2025-07 | O16: 2025-07NGN | P16: 1 | Q16: 31500 | R16: Revenue | S16: Revenue | T16: =IF(AND(S16="Revenue",G16<>"Refunds & Chargebacks"),ABS(Q16),-ABS(Q16)) -> 31500
A17: T100014 | B17: 45840 | C17: POS-Square | D17: Zumi Eats | E17: Website | F17: 4000 | G17: Order Revenue | H17: Website daily settlement 2025-07-02 | I17: NGN | J17: 27600 | L17: INV-20250702-WEB | N17: 2025-07 | O17: 2025-07NGN | P17: 1 | Q17: 27600 | R17: Revenue | S17: Revenue | T17: =IF(AND(S17="Revenue",G17<>"Refunds & Chargebacks"),ABS(Q17),-ABS(Q17)) -> 27600
A18: T100015 | B18: 45840 | C18: POS-Square | D18: Zumi Eats | E18: Aggregator-Glovo | F18: 4000 | G18: Order Revenue | H18: Aggregator-Glovo daily settlement 2025-07-02 | I18: NGN | J18: 27700 | L18: INV-20250702-AGG | N18: 2025-07 | O18: 2025-07NGN | P18: 1 | Q18: 27700 | R18: Revenue | S18: Revenue | T18: =IF(AND(S18="Revenue",G18<>"Refunds & Chargebacks"),ABS(Q18),-ABS(Q18)) -> 27700
A19: T100016 | B19: 45840 | C19: POS-Square | D19: Zumi Eats | E19: Aggregator-Bolt | F19: 4000 | G19: Order Revenue | H19: Aggregator-Bolt daily settlement 2025-07-02 | I19: NGN | J19: 27000 | L19: INV-20250702-AGG | N19: 2025-07 | O19: 2025-07NGN | P19: 1 | Q19: 27000 | R19: Revenue | S19: Revenue | T19: =IF(AND(S19="Revenue",G19<>"Refunds & Chargebacks"),ABS(Q19),-ABS(Q19)) -> 27000
A20: T100017 | B20: 45840 | C20: POS-Square | D20: Zumi Mart | E20: POS-Lekki | F20: 4000 | G20: Order Revenue | H20: POS-Lekki daily settlement 2025-07-02 | I20: NGN | J20: 50900 | L20: INV-20250702-POS | N20: 2025-07 | O20: 2025-07NGN | P20: 1 | Q20: 50900 | R20: Revenue | S20: Revenue | T20: =IF(AND(S20="Revenue",G20<>"Refunds & Chargebacks"),ABS(Q20),-ABS(Q20)) -> 50900
A21: T100018 | B21: 45840 | C21: POS-Square | D21: Zumi Mart | E21: POS-VI | F21: 4000 | G21: Order Revenue | H21: POS-VI daily settlement 2025-07-02 | I21: NGN | J21: 45500 | L21: INV-20250702-POS | N21: 2025-07 | O21: 2025-07NGN | P21: 1 | Q21: 45500 | R21: Revenue | S21: Revenue | T21: =IF(AND(S21="Revenue",G21<>"Refunds & Chargebacks"),ABS(Q21),-ABS(Q21)) -> 45500
A22: T100019 | B22: 45840 | C22: POS-Square | D22: Zumi Mart | E22: POS-Ikeja | F22: 4000 | G22: Order Revenue | H22: POS-Ikeja daily settlement 2025-07-02 | I22: NGN | J22: 48200 | L22: INV-20250702-POS | N22: 2025-07 | O22: 2025-07NGN | P22: 1 | Q22: 48200 | R22: Revenue | S22: Revenue | T22: =IF(AND(S22="Revenue",G22<>"Refunds & Chargebacks"),ABS(Q22),-ABS(Q22)) -> 48200
A23: T100020 | B23: 45840 | C23: POS-Square | D23: Zumi Mart | E23: POS-Abuja | F23: 4000 | G23: Order Revenue | H23: POS-Abuja daily settlement 2025-07-02 | I23: NGN | J23: 46900 | L23: INV-20250702-POS | N23: 2025-07 | O23: 2025-07NGN | P23: 1 | Q23: 46900 | R23: Revenue | S23: Revenue | T23: =IF(AND(S23="Revenue",G23<>"Refunds & Chargebacks"),ABS(Q23),-ABS(Q23)) -> 46900
A24: T100021 | B24: 45840 | C24: POS-Square | D24: Zumi Mart | E24: Online | F24: 4000 | G24: Order Revenue | H24: Online daily settlement 2025-07-02 | I24: NGN | J24: 49800 | L24: INV-20250702-ONL | N24: 2025-07 | O24: 2025-07NGN | P24: 1 | Q24: 49800 | R24: Revenue | S24: Revenue | T24: =IF(AND(S24="Revenue",G24<>"Refunds & Chargebacks"),ABS(Q24),-ABS(Q24)) -> 49800
A25: T100022 | B25: 45840 | C25: NetSuite | D25: Zumi Logistics | E25: Contract-Dangote | F25: 4020 | G25: Logistics Contract Revenue | H25: Contract-Dangote daily settlement 2025-07-02 | I25: USD | J25: 28.56 | K25: Dangote | L25: INV-20250702-CON | N25: 2025-07 | O25: 2025-07USD | P25: 1530 | Q25: 43696.8 | R25: Revenue | S25: Revenue | T25: =IF(AND(S25="Revenue",G25<>"Refunds & Chargebacks"),ABS(Q25),-ABS(Q25)) -> 43696.8
A26: T100023 | B26: 45840 | C26: NetSuite | D26: Zumi Logistics | E26: Contract-MTN | F26: 4020 | G26: Logistics Contract Revenue | H26: Contract-MTN daily settlement 2025-07-02 | I26: NGN | J26: 49900 | K26: MTN | L26: INV-20250702-CON | N26: 2025-07 | O26: 2025-07NGN | P26: 1 | Q26: 49900 | R26: Revenue | S26: Revenue | T26: =IF(AND(S26="Revenue",G26<>"Refunds & Chargebacks"),ABS(Q26),-ABS(Q26)) -> 49900
A27: T100024 | B27: 45840 | C27: NetSuite | D27: Zumi Logistics | E27: Contract-Flutterwave | F27: 4020 | G27: Logistics Contract Revenue | H27: Contract-Flutterwave daily settlement 2025-07-02 | I27: NGN | J27: 48500 | K27: Flutterwave | L27: INV-20250702-CON | N27: 2025-07 | O27: 2025-07NGN | P27: 1 | Q27: 48500 | R27: Revenue | S27: Revenue | T27: =IF(AND(S27="Revenue",G27<>"Refunds & Chargebacks"),ABS(Q27),-ABS(Q27)) -> 48500
A28: T100025 | B28: 45840 | C28: NetSuite | D28: Zumi Logistics | E28: Spot-Market | F28: 4020 | G28: Logistics Contract Revenue | H28: Spot-Market daily settlement 2025-07-02 | I28: NGN | J28: 48000 | L28: INV-20250702-SPO | N28: 2025-07 | O28: 2025-07NGN | P28: 1 | Q28: 48000 | R28: Revenue | S28: Revenue | T28: =IF(AND(S28="Revenue",G28<>"Refunds & Chargebacks"),ABS(Q28),-ABS(Q28)) -> 48000
A29: T101239 | B29: 45840 | C29: QuickBooks | D29: Zumi Eats | F29: 5040 | G29: Rider Payouts | H29: Rider Payroll invoice 2025-07 | I29: NGN | J29: -562000 | K29: Rider Payroll | L29: BILL-47775 | N29: 2025-07 | O29: 2025-07NGN | P29: 1 | Q29: -562000 | R29: COGS | S29: COGS | T29: =IF(AND(S29="Revenue",G29<>"Refunds & Chargebacks"),ABS(Q29),-ABS(Q29)) -> -562000
A30: T101243 | B30: 45840 | C30: QuickBooks | D30: Zumi Eats | F30: 5050 | G30: Aggregator Commission | H30: Bolt Food invoice 2025-07 | I30: NGN | J30: -255000 | K30: Bolt Food | L30: BILL-82046 | N30: 2025-07 | O30: 2025-07NGN | P30: 1 | Q30: -255000 | R30: COGS | S30: COGS | T30: =IF(AND(S30="Revenue",G30<>"Refunds & Chargebacks"),ABS(Q30),-ABS(Q30)) -> -255000
A31: T101254 | B31: 45840 | C31: QuickBooks | D31: Zumi Mart | F31: 5010 | G31: Inventory Purchases | H31: Dangote Sugar invoice 2025-07 | I31: NGN | J31: -862000 | K31: Dangote Sugar | L31: BILL-69162 | N31: 2025-07 | O31: 2025-07NGN | P31: 1 | Q31: -862000 | R31: COGS | S31: COGS | T31: =IF(AND(S31="Revenue",G31<>"Refunds & Chargebacks"),ABS(Q31),-ABS(Q31)) -> -862000
A32: T101394 | B32: 45840 | C32: QuickBooks | D32: Zumi Eats | F32: 6040 | G32: Software & Tools | H32: SaaS subscriptions 2025-07 | I32: USD | J32: -820 | K32: Various SaaS | L32: SAAS-2025-07 | N32: 2025-07 | O32: 2025-07USD | P32: 1530 | Q32: -1254600 | R32: Opex | S32: Opex | T32: =IF(AND(S32="Revenue",G32<>"Refunds & Chargebacks"),ABS(Q32),-ABS(Q32)) -> -1254600
A33: T100026 | B33: 45841 | C33: POS-Square | D33: Zumi Eats | E33: Mobile App | F33: 4000 | G33: Order Revenue | H33: Mobile App daily settlement 2025-07-03 | I33: NGN | J33: 30100 | L33: INV-20250703-MOB | N33: 2025-07 | O33: 2025-07NGN | P33: 1 | Q33: 30100 | R33: Revenue | S33: Revenue | T33: =IF(AND(S33="Revenue",G33<>"Refunds & Chargebacks"),ABS(Q33),-ABS(Q33)) -> 30100
A34: T100027 | B34: 45841 | C34: POS-Square | D34: Zumi Eats | E34: Website | F34: 4000 | G34: Order Revenue | H34: Website daily settlement 2025-07-03 | I34: NGN | J34: 30400 | L34: INV-20250703-WEB | N34: 2025-07 | O34: 2025-07NGN | P34: 1 | Q34: 30400 | R34: Revenue | S34: Revenue | T34: =IF(AND(S34="Revenue",G34<>"Refunds & Chargebacks"),ABS(Q34),-ABS(Q34)) -> 30400
A35: T100028 | B35: 45841 | C35: POS-Square | D35: Zumi Eats | E35: Aggregator-Glovo | F35: 4000 | G35: Order Revenue | H35: Aggregator-Glovo daily settlement 2025-07-03 | I35: NGN | J35: 30700 | L35: INV-20250703-AGG | N35: 2025-07 | O35: 2025-07NGN | P35: 1 | Q35: 30700 | R35: Revenue | S35: Revenue | T35: =IF(AND(S35="Revenue",G35<>"Refunds & Chargebacks"),ABS(Q35),-ABS(Q35)) -> 30700
A36: T100029 | B36: 45841 | C36: POS-Square | D36: Zumi Eats | E36: Aggregator-Bolt | F36: 4000 | G36: Order Revenue | H36: Aggregator-Bolt daily settlement 2025-07-03 | I36: NGN | J36: 28100 | L36: INV-20250703-AGG | N36: 2025-07 | O36: 2025-07NGN | P36: 1 | Q36: 28100 | R36: Revenue | S36: Revenue | T36: =IF(AND(S36="Revenue",G36<>"Refunds & Chargebacks"),ABS(Q36),-ABS(Q36)) -> 28100
A37: T100030 | B37: 45841 | C37: POS-Square | D37: Zumi Mart | E37: POS-Lekki | F37: 4000 | G37: Order Revenue | H37: POS-Lekki daily settlement 2025-07-03 | I37: NGN | J37: 48100 | L37: INV-20250703-POS | N37: 2025-07 | O37: 2025-07NGN | P37: 1 | Q37: 48100 | R37: Revenue | S37: Revenue | T37: =IF(AND(S37="Revenue",G37<>"Refunds & Chargebacks"),ABS(Q37),-ABS(Q37)) -> 48100
